Workbook
Name БР: ИТОГ!$U$42
Name ГИС: ИТОГ!$U$35
Name ЗОКИИ: ИТОГ!$U$37
Name КИИ: ИТОГ!$U$36
Name КТ: ИТОГ!$U$41
Name ЛИЦ: ИТОГ!$U$34
Name Лицензия: ИТОГ!$U$34
Name ПДН: ИТОГ!$U$38
Name СК: ИТОГ!$U$44
Name СКЗИ: ИТОГ!$U$43
Name СКПДН: ИТОГ!$U$39
Name СТОРПДН: ИТОГ!$U$38
Name СУДПДН: ИТОГ!$U$40
Name ЦУКБ: ИТОГ!$L$3

Sheet Описание
D2: Индекс кибербезопасности
B10: Данный файл предназначен для проведения самооценки состояния информационной безопасности и расчета итогового "Индекса кибербезопасности".
B13: Для работы с файлом необходимо заполнить данные в ячейках с желтым фоном на листах с зелеными ярлычками.
B14: На вкладке "ИТОГ" отображается сводный график достижения целевого уровня кибербезопасности.
B15: Лист "Расчет" - это итоговая служебная таблица, на которой осуществляется промежуточный расчет, он не предназначен для редактирования
B18: Рассчет индекса ведется как некоторая усредненная величина показателей по отдельным доменам кибербезопасности.
B19: В каждой отдельной вкладке домена строится своя диаграмма и рассчитывается свой локальный индекс.

Sheet ИТОГ
D2: Итоговый рассчетный индекс кибербезопасности и диаграмма достижения целевых показателей в различных доменах информационной безопасности | L2: Целевой уровень | O2: =IF(ЦУКБ="кб 2", W3, IF(ЦУКБ="КБ 1", U3, Y3)) -> 0 | U2: КБ1 | W2: КБ2 | Y2: КБ3
L3: КБ 3 | P3: на | Q3: =Расчет!M2 -> 46038 | S3: =Расчет!M3 -> 0 | U3: =Расчет!T3 -> 0 | W3: =Расчет!S3 -> 0 | Y3: =Расчет!R3 -> 0
U34: да | V34: Лицензиат ФСТЭК/ФСБ
U35: да | V35: Участие в госконтрактах на разработку/сопровождение ГИС
U36: да | V36: Субьект КИИ
U37: да | V37: Наличие ЗОКИИ
U38: да | V38: Обработка сторонних ПДН
U39: да | V39: Спец. Категории ПДН
U40: да | V40: ПДН о судимости
U41: да | V41: Наличие Коммерческой тайны
U42: да | V42: Безопасная разработка
U43: да | V43: СКЗИ ГОСТ
U44: нет | V44: Подключены сервисы Сервисной Компании

Sheet Расчет
C1: КБ3 | D1: КБ2 | E1: КБ1 | F1: Исторические данные | H1: Исторические данные середину 2024 г. | I1: Исторические данные на конец 2024 г. | J1: Архивные расчетные данные на 31.12.2024 | K1: Расчетные данные на 31.12.2026 | L1: Расчетные данные на | M1: Текущий показатель | N1: Флаг внимания | P1: Степень выполнения расчетного показателя | R1: Степень достижения КБ3 | S1: Степень достижения КБ2 | T1: Степень достижения КБ1
B2: Дата заполнения | F2: 45017 | G2: 45291 | H2: 45444 | M2: =TODAY() -> 46038
B3: ИНДЕКС КИБЕРБЕЗОПАСНОСТИ | C3: =AVERAGE(C4:C44) -> 4.8651098 | D3: =AVERAGE(D4:D44) -> 3.634862 | E3: =AVERAGE(E4:E44) -> 1.8501809 | F3: =0.3*( SUM(F23+F24+F25+F26+F27*IF(СКЗИ="да",1,0)) / (1+1+1+1+1*IF(СКЗИ="да",1,0)) ) +0.2*(SUM(F17+F18*IF(СКЗИ="да",1,0)+(F19+F20)*IF(КИИ="да",1,0)+F22*IF(КТ="да",1,0)) / (1+1*IF(СКЗИ="да",1,0)+(2)*IF(КИИ="да",1,0)+1*IF(КТ="да",1,0)) ) +0.3*(SUM(F4,F21,F28,#REF!,F37,F38)/6) +0.2*(SUM(F39:F44,F29:F36,F6:F14,F16,F5, F15*IF(БР="да",1,0)) / (25+1*IF(БР="да",1,0))) -> #REF! | G3: =0.3*( SUM(G23+G24+G25+G26+G27*IF(СКЗИ="да",1,0)) / (1+1+1+1+1*IF(СКЗИ="да",1,0)) ) +0.2*(SUM(G17+G18*IF(СКЗИ="да",1,0)+(G19+G20)*IF(КИИ="да",1,0)+G22*IF(КТ="да",1,0)) / (1+1*IF(СКЗИ="да",1,0)+(2)*IF(КИИ="да",1,0)+1*IF(КТ="да",1,0)) ) +0.3*(SUM(G4,G21,G28,#REF!,G37,G38)/6) +0.2*(SUM(G39:G44,G29:G36,G6:G14,G16,G5, G15*IF(БР="да",1,0)) / (25+1*IF(БР="да",1,0))) -> #REF! | H3: =0.3*( SUM(H23+H24+H25+H26+H27*IF(СКЗИ="да",1,0)) / (1+1+1+1+1*IF(СКЗИ="да",1,0)) ) +0.2*(SUM(H17+H18*IF(СКЗИ="да",1,0)+(H19+H20)*IF(КИИ="да",1,0)+H22*IF(КТ="да",1,0)) / (1+1*IF(СКЗИ="да",1,0)+(2)*IF(КИИ="да",1,0)+1*IF(КТ="да",1,0)) ) +0.3*(SUM(H4,H21,H28,#REF!,H37,H38)/6) +0.2*(SUM(H39:H44,H29:H36,H6:H14,H16,H5, H15*IF(БР="да",1,0)) / (25+1*IF(БР="да",1,0))) -> #REF! | I3: =0.3*( SUM(I23+I24+I25+I26+I27*IF(СКЗИ="да",1,0)) / (1+1+1+1+1*IF(СКЗИ="да",1,0)) ) +0.2*(SUM(I17+I18*IF(СКЗИ="да",1,0)+(I19+I20)*IF(КИИ="да",1,0)+I22*IF(КТ="да",1,0)) / (1+1*IF(СКЗИ="да",1,0)+(2)*IF(КИИ="да",1,0)+1*IF(КТ="да",1,0)) ) +0.3*(SUM(I4,I21,I28,#REF!,I37,I38)/6) +0.2*(SUM(I39:I44,I29:I36,I6:I14,I16,I5, I15*IF(БР="да",1,0)) / (25+1*IF(БР="да",1,0))) -> #REF! | J3: =0.3*( SUM(J23+J24+J25+J26+J27*IF(СКЗИ="да",1,0)) / (1+1+1+1+1*IF(СКЗИ="да",1,0)) ) +0.2*(SUM(J17+J18*IF(СКЗИ="да",1,0)+(J19+J20)*IF(КИИ="да",1,0)+J22*IF(КТ="да",1,0)) / (1+1*IF(СКЗИ="да",1,0)+(2)*IF(КИИ="да",1,0)+1*IF(КТ="да",1,0)) ) +0.3*(SUM(J4,J21,J28,#REF!,J37,J38)/6) +0.2*(SUM(J39:J44,J29:J36,J6:J14,J16,J5, J15*IF(БР="да",1,0)) / (25+1*IF(БР="да",1,0))) -> #REF! | K3: =0.3*( SUM(K23+K24+K25+K26+K27*IF(СКЗИ="да",1,0)) / (1+1+1+1+1*IF(СКЗИ="да",1,0)) ) +0.2*(SUM(K17+K18*IF(СКЗИ="да",1,0)+(K19+K20)*IF(КИИ="да",1,0)+K22*IF(КТ="да",1,0)) / (1+1*IF(СКЗИ="да",1,0)+(2)*IF(КИИ="да",1,0)+1*IF(КТ="да",1,0)) ) +0.3*(SUM(K4,K21,K28,#REF!,K37,K38)/6) +0.2*(SUM(K39:K44,K29:K36,K6:K14,K16,K5, K15*IF(БР="да",1,0)) / (25+1*IF(БР="да",1,0))) -> #DIV/0! | L3: =AVERAGE(L4:L44) -> 4.8651098 | M3: =AVERAGE(M4:M44) -> 0 | O3: прирост (дек.24- т.вр) | R3: =0.65*( SUM(R23+R24+R25+R26+R27*IF(СКЗИ="да",1,0)+R28+R29+R30+R31+R32+R33+R34+R35+R36) / (1+1+1+1+1*IF(СКЗИ="да",1,0)+5+4) ) +0.2*(SUM(R17+R18*IF(СКЗИ="да",1,0)+(R19+R20)*IF(КИИ="да",1,0)+R21+R22*IF(КТ="да",1,0)) / (1+IF(СКЗИ="да",1,0)+(2)*IF(КИИ="да",1,0)+1+IF(КТ="да",1,0)) ) +0.15*(SUM(R4:R13,R15,R16,R37:R44) / (10+1+1+8)) -> 0 | S3: =0.65*( SUM(S23+S24+S25+S26+S27*IF(СКЗИ="да",1,0)+S28+S29+S30+S31+S32+S33)/(1+1+1+1+1*IF(СКЗИ="да",1,0)+6)) +0.2*(SUM(S17+S18*IF(СКЗИ="да",1,0)+(S19+S20)*IF(КИИ="да",1,0)+S21+S22*IF(КТ="да",1,0))/(1+IF(СКЗИ="да",1,0)+(2)*IF(КИИ="да",1,0)+1+IF(КТ="да",1,0)) ) +0.15*(SUM(S4:S13,S15,S16,S37:S44) / (10+1+1+8)) -> 0 | T3: =0.65*( SUM(T23+T24+T25+T26+T27*IF(СКЗИ="да",1,0)) / (1+1+1+1+1*IF(СКЗИ="да",1,0)) ) +0.2*(SUM(T17+T18*IF(СКЗИ="да",1,0)+(T19+T20)*IF(КИИ="да",1,0)+T21+T22*IF(КТ="да",1,0)) / (1+IF(СКЗИ="да",1,0)+(2)*IF(КИИ="да",1,0)+1+IF(КТ="да",1,0)) ) +0.15*(SUM(T4:T10,T12:T13,T15,T16,T39:T43) / (9+1+1+5)) -> 0
A4: СУИБ | B4: ='Управление ИБ'!B42 -> Система управления ИБ | C4: ='Управление ИБ'!D42 -> 5 | D4: ='Управление ИБ'!E42 -> 4.64 | E4: ='Управление ИБ'!F42 -> 2.5 | F4: 0 | G4: 0 | H4: 0 | I4: 0 | J4: 0 | K4: ='Управление ИБ'!J42 -> #DIV/0! | L4: ='Управление ИБ'!K42 -> 5 | M4: ='Управление ИБ'!L42 -> 0 | N4: =L4-M4 -> 5 | O4: =I4-M4 -> 0 | P4: =1-IF(L4=0,0,IF(($M4-L4)>=0,1,1-(L4-$M4)/L4)) -> 1 | R4: ='Управление ИБ'!P42 -> 0 | S4: ='Управление ИБ'!Q42 -> 0 | T4: ='Управление ИБ'!R42 -> 0
B5: ='Управление ИБ'!B43 -> Управление рисками | C5: ='Управление ИБ'!D43 -> 4.8 | D5: ='Управление ИБ'!E43 -> 2 | E5: ='Управление ИБ'!F43 -> 1 | F5: 0 | G5: 0 | H5: 0 | I5: 0 | J5: 0 | K5: ='Управление ИБ'!J43 -> #DIV/0! | L5: ='Управление ИБ'!K43 -> 4.8 | M5: ='Управление ИБ'!L43 -> 0 | N5: =L5-M5 -> 4.8 | O5: =I5-M5 -> 0 | P5: =1-IF(L5=0,0,IF(($M5-L5)>=0,1,1-(L5-$M5)/L5)) -> 1 | R5: ='Управление ИБ'!P43 -> 0 | S5: ='Управление ИБ'!Q43 -> 0 | T5: ='Управление ИБ'!R43 -> 0
B6: ='Управление ИБ'!B45 -> Инвентаризация | C6: ='Управление ИБ'!D45 -> 4.9285714 | D6: ='Управление ИБ'!E45 -> 3.1857143 | E6: ='Управление ИБ'!F45 -> 1.2142857 | F6: 0 | G6: 0 | H6: 0 | I6: 0 | J6: 0 | K6: ='Управление ИБ'!J45 -> #DIV/0! | L6: ='Управление ИБ'!K45 -> 4.9285714 | M6: ='Управление ИБ'!L45 -> 0 | N6: =L6-M6 -> 4.9285714 | O6: =I6-M6 -> 0 | P6: =1-IF(L6=0,0,IF(($M6-L6)>=0,1,1-(L6-$M6)/L6)) -> 1 | R6: ='Управление ИБ'!P45 -> 0 | S6: ='Управление ИБ'!Q45 -> 0 | T6: ='Управление ИБ'!R45 -> 0
B7: ='Управление ИБ'!B46 -> Управление активами | C7: ='Управление ИБ'!D46 -> 4.8 | D7: ='Управление ИБ'!E46 -> 3.16 | E7: ='Управление ИБ'!F46 -> 0.52 | F7: 0 | G7: 0 | H7: 0 | I7: 0 | J7: 0 | K7: ='Управление ИБ'!J46 -> #DIV/0! | L7: ='Управление ИБ'!K46 -> 4.8 | M7: ='Управление ИБ'!L46 -> 0 | N7: =L7-M7 -> 4.8 | O7: =I7-M7 -> 0 | P7: =1-IF(L7=0,0,IF(($M7-L7)>=0,1,1-(L7-$M7)/L7)) -> 1 | R7: ='Управление ИБ'!P46 -> 0 | S7: ='Управление ИБ'!Q46 -> 0 | T7: ='Управление ИБ'!R46 -> 0
B8: ='Управление ИБ'!B47 -> Управление доступом | C8: ='Управление ИБ'!D47 -> 4.46 | D8: ='Управление ИБ'!E47 -> 3.26 | E8: ='Управление ИБ'!F47 -> 2.14 | F8: 0 | G8: 0 | H8: 0 | I8: 0 | J8: 0 | K8: ='Управление ИБ'!J47 -> #DIV/0! | L8: ='Управление ИБ'!K47 -> 4.46 | M8: ='Управление ИБ'!L47 -> 0 | N8: =L8-M8 -> 4.46 | O8: =I8-M8 -> 0 | P8: =1-IF(L8=0,0,IF(($M8-L8)>=0,1,1-(L8-$M8)/L8)) -> 1 | R8: ='Управление ИБ'!P47 -> 0 | S8: ='Управление ИБ'!Q47 -> 0 | T8: ='Управление ИБ'!R47 -> 0
B9: ='Управление ИБ'!B48 -> Идентификация и аутентификация | C9: ='Управление ИБ'!D48 -> 5 | D9: ='Управление ИБ'!E48 -> 4.6 | E9: ='Управление ИБ'!F48 -> 3.3111111 | F9: 0 | G9: 0 | H9: 0 | I9: 0 | J9: 0 | K9: ='Управление ИБ'!J48 -> #DIV/0! | L9: ='Управление ИБ'!K48 -> 5 | M9: ='Управление ИБ'!L48 -> 0 | N9: =L9-M9 -> 5 | O9: =I9-M9 -> 0 | P9: =1-IF(L9=0,0,IF(($M9-L9)>=0,1,1-(L9-$M9)/L9)) -> 1 | R9: ='Управление ИБ'!P48 -> 0 | S9: ='Управление ИБ'!Q48 -> 0 | T9: ='Управление ИБ'!R48 -> 0
B10: ='Управление ИБ'!B49 -> Защита данных и информации | C10: ='Управление ИБ'!D49 -> 4.55 | D10: ='Управление ИБ'!E49 -> 3.7 | E10: ='Управление ИБ'!F49 -> 1.2 | F10: 0 | G10: 0 | H10: 0 | I10: 0 | J10: 0 | K10: ='Управление ИБ'!J49 -> #DIV/0! | L10: ='Управление ИБ'!K49 -> 4.55 | M10: ='Управление ИБ'!L49 -> 0 | N10: =L10-M10 -> 4.55 | O10: =I10-M10 -> 0 | P10: =1-IF(L10=0,0,IF(($M10-L10)>=0,1,1-(L10-$M10)/L10)) -> 1 | R10: ='Управление ИБ'!P49 -> 0 | S10: ='Управление ИБ'!Q49 -> 0 | T10: ='Управление ИБ'!R49 -> 0
B11: ='Управление ИБ'!B50 -> Обеспечение доступности | C11: ='Управление ИБ'!D50 -> 5 | D11: ='Управление ИБ'!E50 -> 2.92 | E11: ='Управление ИБ'!F50 -> 0 | F11: 0 | G11: 0 | H11: 0 | I11: 0 | J11: 0 | K11: ='Управление ИБ'!J50 -> #DIV/0! | L11: ='Управление ИБ'!K50 -> 5 | M11: ='Управление ИБ'!L50 -> 0 | N11: =L11-M11 -> 5 | O11: =I11-M11 -> 0 | P11: =1-IF(L11=0,0,IF(($M11-L11)>=0,1,1-(L11-$M11)/L11)) -> 1 | R11: ='Управление ИБ'!P50 -> 0 | S11: ='Управление ИБ'!Q50 -> 0
B12: ='Управление ИБ'!B51 -> Персонал | C12: ='Управление ИБ'!D51 -> 5 | D12: ='Управление ИБ'!E51 -> 5 | E12: ='Управление ИБ'!F51 -> 5 | F12: 0 | G12: 0 | H12: 0 | I12: 0 | J12: 0 | K12: ='Управление ИБ'!J51 -> #DIV/0! | L12: ='Управление ИБ'!K51 -> 5 | M12: ='Управление ИБ'!L51 -> 0 | N12: =L12-M12 -> 5 | O12: =I12-M12 -> 0 | P12: =1-IF(L12=0,0,IF(($M12-L12)>=0,1,1-(L12-$M12)/L12)) -> 1 | R12: ='Управление ИБ'!P51 -> 0 | S12: ='Управление ИБ'!Q51 -> 0 | T12: ='Управление ИБ'!R51 -> 0
B13: ='Управление ИБ'!B52 -> Осведомленность пользователей и обучение персонала | C13: ='Управление ИБ'!D52 -> 5 | D13: ='Управление ИБ'!E52 -> 3.2 | E13: ='Управление ИБ'!F52 -> 1.6 | F13: 0 | G13: 0 | H13: 0 | I13: 0 | J13: 0 | K13: ='Управление ИБ'!J52 -> #DIV/0! | L13: ='Управление ИБ'!K52 -> 5 | M13: ='Управление ИБ'!L52 -> 0 | N13: =L13-M13 -> 5 | O13: =I13-M13 -> 0 | P13: =1-IF(L13=0,0,IF(($M13-L13)>=0,1,1-(L13-$M13)/L13)) -> 1 | R13: ='Управление ИБ'!P52 -> 0 | S13: ='Управление ИБ'!Q52 -> 0 | T13: ='Управление ИБ'!R52 -> 0
B14: ='Управление ИБ'!B53 -> Процессы | C14: ='Управление ИБ'!D53 -> 4.1428571 | D14: ='Управление ИБ'!E53 -> 2.7904762 | E14: ='Управление ИБ'!F53 -> 0.6952381 | F14: 0 | G14: 0 | H14: 0 | I14: 0 | J14: 0 | K14: ='Управление ИБ'!J53 -> 0 | L14: ='Управление ИБ'!K53 -> 4.1428571 | M14: ='Управление ИБ'!L53 -> 0 | N14: =L14-M14 -> 4.1428571 | O14: =I14-M14 -> 0 | P14: =1-IF(L14=0,0,IF(($M14-L14)>=0,1,1-(L14-$M14)/L14)) -> 1
B15: ='Управление ИБ'!B54 -> Приобретение, разработка и обслуживание систем и ПО | C15: ='Управление ИБ'!D54 -> 5 | D15: ='Управление ИБ'!E54 -> 3.8545455 | E15: ='Управление ИБ'!F54 -> 1.0181818 | F15: 0 | G15: 0 | H15: 0 | I15: 0 | J15: 0 | K15: ='Управление ИБ'!J54 -> #DIV/0! | L15: ='Управление ИБ'!K54 -> 5 | M15: ='Управление ИБ'!L54 -> 0 | N15: =L15-M15 -> 5 | O15: =I15-M15 -> 0 | P15: =1-IF(L15=0,0,IF(($M15-L15)>=0,1,1-(L15-$M15)/L15)) -> 1 | R15: ='Управление ИБ'!P54 -> 0 | S15: ='Управление ИБ'!Q54 -> 0 | T15: ='Управление ИБ'!R54 -> 0
B16: ='Управление ИБ'!B55 -> Физический доступ | C16: ='Управление ИБ'!D55 -> 5 | D16: ='Управление ИБ'!E55 -> 4.64 | E16: ='Управление ИБ'!F55 -> 4.32 | F16: 0 | G16: 0 | H16: 0 | I16: 0 | J16: 0 | K16: ='Управление ИБ'!J55 -> #DIV/0! | L16: ='Управление ИБ'!K55 -> 5 | M16: ='Управление ИБ'!L55 -> 0 | N16: =L16-M16 -> 5 | O16: =I16-M16 -> 0 | P16: =1-IF(L16=0,0,IF(($M16-L16)>=0,1,1-(L16-$M16)/L16)) -> 1 | R16: ='Управление ИБ'!P55 -> 0 | S16: ='Управление ИБ'!Q55 -> 0 | T16: ='Управление ИБ'!R55 -> 0
A17: ='Нормативное соответствие'!B1 -> Нормативное соответствие | B17: ='Нормативное соответствие'!B42 -> Персональные данные | C17: ='Нормативное соответствие'!D42 -> 5 | D17: ='Нормативное соответствие'!E42 -> 5 | E17: ='Нормативное соответствие'!F42 -> 5 | F17: 0 | G17: 0 | H17: 0 | I17: 0 | J17: 0 | K17: ='Нормативное соответствие'!J42 -> #DIV/0! | L17: ='Нормативное соответствие'!K42 -> 5 | M17: ='Нормативное соответствие'!L42 -> 0 | N17: =L17-M17 -> 5 | O17: =I17-M17 -> 0 | P17: =1-IF(L17=0,0,IF(($M17-L17)>=0,1,1-(L17-$M17)/L17)) -> 1 | R17: =IF(C17=0,0,IF(($M17-C17)>=0,1,1-(C17-$M17)/C17)) -> 0 | S17: =IF(D17=0,0,IF(($M17-D17)>=0,1,1-(D17-$M17)/D17)) -> 0 | T17: =IF(E17=0,0,IF(($M17-E17)>=0,1,1-(E17-$M17)/E17)) -> 0
B18: СКЗИ (ГОСТ) | C18: ='Нормативное соответствие'!D45 -> 5 | D18: ='Нормативное соответствие'!E45 -> 5 | E18: ='Нормативное соответствие'!F45 -> 5 | F18: 0 | G18: 0 | H18: 0 | I18: 0 | J18: 0 | K18: ='Нормативное соответствие'!J45 -> #DIV/0! | L18: ='Нормативное соответствие'!K45 -> 5 | M18: ='Нормативное соответствие'!L45 -> 0 | N18: =L18-M18 -> 5 | O18: =I18-M18 -> 0 | P18: =1-IF(L18=0,0,IF(($M18-L18)>=0,1,1-(L18-$M18)/L18)) -> 1 | R18: =IF(C18=0,0,IF(($M18-C18)>=0,1,1-(C18-$M18)/C18)) -> 0 | S18: =IF(D18=0,0,IF(($M18-D18)>=0,1,1-(D18-$M18)/D18)) -> 0 | T18: =IF(E18=0,0,IF(($M18-E18)>=0,1,1-(E18-$M18)/E18)) -> 0
B19: ='Нормативное соответствие'!B43 -> КИИ | C19: ='Нормативное соответствие'!D43 -> 5 | D19: ='Нормативное соответствие'!E43 -> 5 | E19: ='Нормативное соответствие'!F43 -> 2.88 | F19: 0 | G19: 0 | H19: 0 | I19: 0 | J19: 0 | K19: ='Нормативное соответствие'!J43 -> #DIV/0! | L19: ='Нормативное соответствие'!K43 -> 5 | M19: ='Нормативное соответствие'!L43 -> 0 | N19: =L19-M19 -> 5 | O19: =I19-M19 -> 0 | P19: =1-IF(L19=0,0,IF(($M19-L19)>=0,1,1-(L19-$M19)/L19)) -> 1 | R19: =IF(C19=0,0,IF(($M19-C19)>=0,1,1-(C19-$M19)/C19)) -> 0 | S19: =IF(D19=0,0,IF(($M19-D19)>=0,1,1-(D19-$M19)/D19)) -> 0 | T19: =IF(E19=0,0,IF(($M19-E19)>=0,1,1-(E19-$M19)/E19)) -> 0
B20: ='Нормативное соответствие'!B46 -> 250 указ | C20: ='Нормативное соответствие'!D46 -> 5 | D20: ='Нормативное соответствие'!E46 -> 5 | E20: ='Нормативное соответствие'!F46 -> 5 | F20: 0 | G20: 0 | H20: 0 | I20: 0 | J20: 0 | K20: ='Нормативное соответствие'!J46 -> #DIV/0! | L20: ='Нормативное соответствие'!K46 -> 5 | M20: ='Нормативное соответствие'!L46 -> 0 | N20: =L20-M20 -> 5 | O20: =I20-M20 -> 0 | P20: =1-IF(L20=0,0,IF(($M20-L20)>=0,1,1-(L20-$M20)/L20)) -> 1 | R20: =IF(C20=0,0,IF(($M20-C20)>=0,1,1-(C20-$M20)/C20)) -> 0 | S20: =IF(D20=0,0,IF(($M20-D20)>=0,1,1-(D20-$M20)/D20)) -> 0 | T20: =IF(E20=0,0,IF(($M20-E20)>=0,1,1-(E20-$M20)/E20)) -> 0
B21: ='Управление ИБ'!B44 -> Управление рисками в цепочке поставок | C21: ='Управление ИБ'!D44 -> 5 | D21: ='Управление ИБ'!E44 -> 3.8 | E21: ='Управление ИБ'!F44 -> 2.7333333 | F21: 0 | G21: 0 | H21: 0 | I21: 0 | J21: 0 | K21: ='Управление ИБ'!J44 -> #DIV/0! | L21: ='Управление ИБ'!K44 -> 5 | M21: ='Управление ИБ'!L44 -> 0 | N21: =L21-M21 -> 5 | O21: =I21-M21 -> 0 | P21: =1-IF(L21=0,0,IF(($M21-L21)>=0,1,1-(L21-$M21)/L21)) -> 1 | R21: ='Управление ИБ'!P44 -> 0 | S21: ='Управление ИБ'!Q44 -> 0 | T21: ='Управление ИБ'!R44 -> 0
B22: ='Нормативное соответствие'!B44 -> Коммерческая тайна | C22: ='Нормативное соответствие'!D44 -> 5 | D22: ='Нормативное соответствие'!E44 -> 5 | E22: ='Нормативное соответствие'!F44 -> 5 | F22: 0 | G22: 0 | H22: 0 | I22: 0 | J22: 0 | K22: ='Нормативное соответствие'!J44 -> #DIV/0! | L22: ='Нормативное соответствие'!K44 -> 5 | M22: ='Нормативное соответствие'!L44 -> 0 | N22: =L22-M22 -> 5 | O22: =I22-M22 -> 0 | P22: =1-IF(L22=0,0,IF(($M22-L22)>=0,1,1-(L22-$M22)/L22)) -> 1 | R22: =IF(C22=0,0,IF(($M22-C22)>=0,1,1-(C22-$M22)/C22)) -> 0 | S22: =IF(D22=0,0,IF(($M22-D22)>=0,1,1-(D22-$M22)/D22)) -> 0 | T22: =IF(E22=0,0,IF(($M22-E22)>=0,1,1-(E22-$M22)/E22)) -> 0
A23: СЗИ | B23: =СЗИ!B29 -> Защита от ВПО | C23: =СЗИ!D29 -> 4.59375 | D23: =СЗИ!E29 -> 4.1875 | E23: =СЗИ!F29 -> 3.04375 | F23: 0 | G23: 0 | H23: 0 | I23: 0 | J23: 0 | K23: =СЗИ!J29 -> #DIV/0! | L23: =СЗИ!K29 -> 4.59375 | M23: =СЗИ!L29 -> 0 | N23: =L23-M23 -> 4.59375 | O23: =I23-M23 -> 0 | P23: =1-IF(L23=0,0,IF(($M23-L23)>=0,1,1-(L23-$M23)/L23)) -> 1 | R23: =СЗИ!P29 -> 0 | S23: =СЗИ!Q29 -> 0 | T23: =СЗИ!R29 -> 0
B24: 2FA | C24: =СЗИ!D30 -> 5 | D24: =СЗИ!E30 -> 5 | E24: =СЗИ!F30 -> 5 | F24: 0 | G24: 0 | H24: 0 | I24: 0 | J24: 0 | K24: =СЗИ!J30 -> 0 | L24: =СЗИ!K30 -> 5 | M24: =СЗИ!L30 -> 0 | N24: =L24-M24 -> 5 | O24: =I24-M24 -> 0 | P24: =1-IF(L24=0,0,IF(($M24-L24)>=0,1,1-(L24-$M24)/L24)) -> 1 | R24: =СЗИ!P30 -> 0 | S24: =СЗИ!Q30 -> 0 | T24: =СЗИ!R30 -> 0
B25: CPT | C25: =СЗИ!D31 -> 4.6666667 | D25: =СЗИ!E31 -> 4.3333333 | E25: =СЗИ!F31 -> 3.6666667 | F25: 0 | G25: 0 | H25: 0 | I25: 0 | J25: 0 | K25: =СЗИ!J31 -> 0 | L25: =СЗИ!K31 -> 4.6666667 | M25: =СЗИ!L31 -> 0 | N25: =L25-M25 -> 4.6666667 | O25: =I25-M25 -> 0 | P25: =1-IF(L25=0,0,IF(($M25-L25)>=0,1,1-(L25-$M25)/L25)) -> 1 | R25: =СЗИ!P31 -> 0 | S25: =СЗИ!Q31 -> 0 | T25: =СЗИ!R31 -> 0
B26: RA VPN | C26: =СЗИ!D32 -> 5 | D26: =СЗИ!E32 -> 5 | E26: =СЗИ!F32 -> 4.55 | F26: 0 | G26: 0 | H26: 0 | I26: 0 | J26: 0 | K26: =СЗИ!J32 -> 0 | L26: =СЗИ!K32 -> 5 | M26: =СЗИ!L32 -> 0 | N26: =L26-M26 -> 5 | O26: =I26-M26 -> 0 | P26: =1-IF(L26=0,0,IF(($M26-L26)>=0,1,1-(L26-$M26)/L26)) -> 1 | R26: =СЗИ!P32 -> 0 | S26: =СЗИ!Q32 -> 0 | T26: =СЗИ!R32 -> 0
B27: СКЗИ (ГОСТ) Site-to-Site | C27: =СЗИ!D33 -> 5 | D27: =СЗИ!E33 -> 5 | E27: =СЗИ!F33 -> 4.4 | F27: 0 | G27: 0 | H27: 0 | I27: 0 | J27: 0 | K27: =СЗИ!J33 -> 0 | L27: =СЗИ!K33 -> 5 | M27: =СЗИ!L33 -> 0 | N27: =L27-M27 -> 5 | O27: =I27-M27 -> 0 | P27: =1-IF(L27=0,0,IF(($M27-L27)>=0,1,1-(L27-$M27)/L27)) -> 1 | R27: =СЗИ!P33 -> 0 | S27: =СЗИ!Q33 -> 0 | T27: =СЗИ!R33 -> 0
B28: =Мониторинг!B39 -> SIEM (внедрение системы как СЗИ) | C28: =СЗИ!D34 -> 4.9038462 | D28: =СЗИ!E34 -> 3.5230769 | E28: =СЗИ!F34 -> 0 | F28: 0 | G28: 0 | H28: 0 | I28: 0 | J28: 0 | K28: =СЗИ!J34 -> #DIV/0! | L28: =СЗИ!K34 -> 4.9038462 | M28: =СЗИ!L34 -> 0 | N28: =L28-M28 -> 4.9038462 | O28: =I28-M28 -> 0 | P28: =1-IF(L28=0,0,IF(($M28-L28)>=0,1,1-(L28-$M28)/L28)) -> 1 | R28: =СЗИ!P34 -> 0 | S28: =СЗИ!Q34 -> 0
B29: МСЭ\NGFW | C29: =СЗИ!D35 -> 5 | D29: =СЗИ!E35 -> 4.1 | E29: =СЗИ!F35 -> 0 | F29: 0 | G29: 0 | H29: 0 | I29: 0 | J29: 0 | K29: =СЗИ!J35 -> #DIV/0! | L29: =СЗИ!K35 -> 5 | M29: =СЗИ!L35 -> 0 | N29: =L29-M29 -> 5 | O29: =I29-M29 -> 0 | P29: =1-IF(L29=0,0,IF(($M29-L29)>=0,1,1-(L29-$M29)/L29)) -> 1 | R29: =СЗИ!P35 -> 0 | S29: =СЗИ!Q35 -> 0
B30: Прокси-сервер | C30: =СЗИ!D36 -> 5 | D30: =СЗИ!E36 -> 3.025 | E30: =СЗИ!F36 -> 0 | F30: 0 | G30: 0 | H30: 0 | I30: 0 | J30: 0 | K30: =СЗИ!J36 -> #DIV/0! | L30: =СЗИ!K36 -> 5 | M30: =СЗИ!L36 -> 0 | N30: =L30-M30 -> 5 | O30: =I30-M30 -> 0 | P30: =1-IF(L30=0,0,IF(($M30-L30)>=0,1,1-(L30-$M30)/L30)) -> 1 | R30: =СЗИ!P36 -> 0 | S30: =СЗИ!Q36 -> 0
B31: =СЗИ!B37 -> Сканер уязвимостей | C31: =СЗИ!D37 -> 4.6666667 | D31: =СЗИ!E37 -> 3.7333333 | E31: =СЗИ!F37 -> 0 | F31: 0 | G31: 0 | H31: 0 | I31: 0 | J31: 0 | K31: =СЗИ!J37 -> #DIV/0! | L31: =СЗИ!K37 -> 4.6666667 | M31: =СЗИ!L37 -> 0 | N31: =L31-M31 -> 4.6666667 | O31: =I31-M31 -> 0 | P31: =1-IF(L31=0,0,IF(($M31-L31)>=0,1,1-(L31-$M31)/L31)) -> 1 | R31: =СЗИ!P37 -> 0 | S31: =СЗИ!Q37 -> 0
B32: Anti-DDoS | C32: =СЗИ!D38 -> 5 | D32: =СЗИ!E38 -> 3.8 | E32: =СЗИ!F38 -> 0 | F32: 0 | G32: 0 | H32: 0 | I32: 0 | J32: 0 | K32: =СЗИ!J38 -> #DIV/0! | L32: =СЗИ!K38 -> 5 | M32: =СЗИ!L38 -> 0 | N32: =L32-M32 -> 5 | O32: =I32-M32 -> 0 | P32: =1-IF(L32=0,0,IF(($M32-L32)>=0,1,1-(L32-$M32)/L32)) -> 1 | R32: =СЗИ!P38 -> 0 | S32: =СЗИ!Q38 -> 0
B33: AntiSPAM | C33: =СЗИ!D39 -> 5 | D33: =СЗИ!E39 -> 5 | E33: =СЗИ!F39 -> 0 | F33: 0 | G33: 0 | H33: 0 | I33: 0 | J33: 0 | K33: =СЗИ!J39 -> #DIV/0! | L33: =СЗИ!K39 -> 5 | M33: =СЗИ!L39 -> 0 | N33: =L33-M33 -> 5 | O33: =I33-M33 -> 0 | P33: =1-IF(L33=0,0,IF(($M33-L33)>=0,1,1-(L33-$M33)/L33)) -> 1 | R33: =СЗИ!P39 -> 0 | S33: =СЗИ!Q39 -> 0
B34: WAF | C34: =СЗИ!D40 -> 5 | D34: =СЗИ!E40 -> 0 | E34: =СЗИ!F40 -> 0 | F34: 0 | G34: 0 | H34: 0 | I34: 0 | J34: 0 | K34: =СЗИ!J40 -> #DIV/0! | L34: =СЗИ!K40 -> 5 | M34: =СЗИ!L40 -> 0 | N34: =L34-M34 -> 5 | O34: =I34-M34 -> 0 | P34: =1-IF(L34=0,0,IF(($M34-L34)>=0,1,1-(L34-$M34)/L34)) -> 1 | R34: =СЗИ!P40 -> 0
B35: PAM | C35: =СЗИ!D41 -> 5 | D35: =СЗИ!E41 -> 0 | E35: =СЗИ!F41 -> 0 | F35: 0 | G35: 0 | H35: 0 | I35: 0 | J35: 0 | K35: =СЗИ!J41 -> 0 | L35: =СЗИ!K41 -> 5 | M35: =СЗИ!L41 -> 0 | N35: =L35-M35 -> 5 | O35: =I35-M35 -> 0 | P35: =1-IF(L35=0,0,IF(($M35-L35)>=0,1,1-(L35-$M35)/L35)) -> 1 | R35: =СЗИ!P41 -> 0
B36: DLP | C36: =СЗИ!D42 -> 4.8571429 | D36: =СЗИ!E42 -> 0 | E36: =СЗИ!F42 -> 0 | F36: 0 | G36: 0 | H36: 0 | I36: 0 | J36: 0 | K36: =СЗИ!J42 -> 0 | L36: =СЗИ!K42 -> 4.8571429 | M36: =СЗИ!L42 -> 0 | N36: =L36-M36 -> 4.8571429 | O36: =I36-M36 -> 0 | P36: =1-IF(L36=0,0,IF(($M36-L36)>=0,1,1-(L36-$M36)/L36)) -> 1 | R36: =СЗИ!P42 -> 0
B37: Аномалии и хранение событий | C37: =Мониторинг!D38 -> 5 | D37: =Мониторинг!E38 -> 5 | E37: =Мониторинг!F38 -> 0 | F37: 0 | G37: 0 | H37: 0 | I37: 0 | J37: 0 | K37: =Мониторинг!J38 -> #DIV/0! | L37: =Мониторинг!K38 -> 5 | M37: =Мониторинг!L38 -> 0 | N37: =L37-M37 -> 5 | O37: =I37-M37 -> 0 | P37: =1-IF(L37=0,0,IF(($M37-L37)>=0,1,1-(L37-$M37)/L37)) -> 1 | R37: =IF(C37=0,0,IF(($M37-C37)>=0,1,1-(C37-$M37)/C37)) -> 0 | S37: =IF(D37=0,0,IF(($M37-D37)>=0,1,1-(D37-$M37)/D37)) -> 0
B38: =Мониторинг!B40 -> Мониторинг - Процессы | C38: =Мониторинг!D40 -> 4 | D38: =Мониторинг!E40 -> 2.6 | E38: =Мониторинг!F40 -> 0 | F38: 0 | G38: 0 | H38: 0 | I38: 0 | J38: 0 | K38: =Мониторинг!J40 -> #DIV/0! | L38: =Мониторинг!K40 -> 4 | M38: =Мониторинг!L40 -> 0 | N38: =L38-M38 -> 4 | O38: =I38-M38 -> 0 | P38: =1-IF(L38=0,0,IF(($M38-L38)>=0,1,1-(L38-$M38)/L38)) -> 1 | R38: =IF(C38=0,0,IF(($M38-C38)>=0,1,1-(C38-$M38)/C38)) -> 0 | S38: =IF(D38=0,0,IF(($M38-D38)>=0,1,1-(D38-$M38)/D38)) -> 0
A39: Реагирование | B39: =Реагирование!B30 -> Планирование реагирования | C39: =Реагирование!D30 -> 4.5 | D39: =Реагирование!E30 -> 3.1 | E39: =Реагирование!F30 -> 0.5 | F39: 0 | G39: 0 | H39: 0 | I39: 0 | J39: 0 | K39: =Реагирование!J30 -> #DIV/0! | L39: =Реагирование!K30 -> 4.5 | M39: =Реагирование!L30 -> 0 | N39: =L39-M39 -> 4.5 | O39: =I39-M39 -> 0 | P39: =1-IF(L39=0,0,IF(($M39-L39)>=0,1,1-(L39-$M39)/L39)) -> 1 | R39: =IF(C39=0,0,IF(($M39-C39)>=0,1,1-(C39-$M39)/C39)) -> 0 | S39: =IF(D39=0,0,IF(($M39-D39)>=0,1,1-(D39-$M39)/D39)) -> 0 | T39: =IF(E39=0,0,IF(($M39-E39)>=0,1,1-(E39-$M39)/E39)) -> 0
B40: =Реагирование!B31 -> Коммуникации (реагирование на инциденты) | C40: =Реагирование!D31 -> 5 | D40: =Реагирование!E31 -> 3.2 | E40: =Реагирование!F31 -> 0.64 | F40: 0 | G40: 0 | H40: 0 | I40: 0 | J40: 0 | K40: =Реагирование!J31 -> #DIV/0! | L40: =Реагирование!K31 -> 5 | M40: =Реагирование!L31 -> 0 | N40: =L40-M40 -> 5 | O40: =I40-M40 -> 0 | P40: =1-IF(L40=0,0,IF(($M40-L40)>=0,1,1-(L40-$M40)/L40)) -> 1 | R40: =IF(C40=0,0,IF(($M40-C40)>=0,1,1-(C40-$M40)/C40)) -> 0 | S40: =IF(D40=0,0,IF(($M40-D40)>=0,1,1-(D40-$M40)/D40)) -> 0 | T40: =IF(E40=0,0,IF(($M40-E40)>=0,1,1-(E40-$M40)/E40)) -> 0
...

Sheet Программа
A1: ПЛАН ОБЕСПЕЧЕНИЯ И РАЗВИТИЯ ИБ ООО "РОМАШКА" НА 2026 г.
A2: СОГЛАСОВАНО: | S2: УТВЕРЖДЕНО:
A3: Вице-Президент по развитию и обеспечению информационной безопасности ПАО "Ростелеком" | O3: Рекомендации по заполнению (удалить при печати): 1. Столбец "Индикатор (статус выполнения)" используем для формирования программы, используя фильтр: цвет ячейки - Красный; 2. Столбец "Мероприятия ДЗО" предназначен для формирования мероприятий применимых к конкретному ДЗО, с учетом специфики и достаточным уровнем детализации, сформированных в соответствии с рекомендациями Блока ИБ (столбец - "Рекомендации ПАО"); 3. Столбец "Доп .ФОТ (руб.)" не требуется разбивать по каждой статье (мероприятию), достаточно указать в одном мероприятии полную стоимость затрат на ФОТ. | S3: Генеральный директор ООО "Ромашка"
A4: Чугунов А.В. | W4: Иванов И.И.
A5: (ФИО) | D5: (Подпись) | S5: (Подпись) | W5: (ФИО)
A6: 13.11.2025 г. | W6: 13.11.2025 г.
A7: (Дата) | W7: (Дата)
A8: Тематика | B8: Домен | C8: Наименование показателя | D8: Сокращенное наименование | E8: КБ3 | F8: КБ2 | G8: КБ1 | H8: Приоритет | I8: Уровень КБ | L8: =SUBTOTAL(3,L10:L9523) -> 76 | N8: ="Всего: " & SUBTOTAL(3,N10:N9523) -> Всего: 76 | O8: ="Всего: " & SUBTOTAL(3,O10:O9523) -> Всего: 76 | P8: ="Всего: " & SUBTOTAL(3,P10:P9523) -> Всего: 76 | Q8: ="Всего: " & SUBTOTAL(3,Q10:Q9523) -> Всего: 76 | R8: ="Всего: " & SUBTOTAL(3,R10:R9523) -> Всего: 0 | S8: Плановый срок выполнения | T8: Статус | U8: =SUBTOTAL(9,U10:U453) -> 0 | V8: =SUBTOTAL(9,V10:V453) -> 0 | W8: =SUBTOTAL(9,W10:W453) -> 0 | X8: =SUBTOTAL(9,X10:X453) -> 0
J9: Расчетный показатель 2025 | K9: Начальный показатель (на 01.25) | L9: Текущий показатель | M9: Динамика | N9: Индикатор (статус выполнения) | O9: Рекомендации ПАО | P9: Мероприятия ДЗО | Q9: Артефакты достижения | R9: Методика проверки | U9: CAPEX (руб.) | V9: OPEX (руб.) | W9: Доп. ФОТ (руб.) | X9: Итог (руб.)
A10: Восстановление | B10: Планирование восстановления | C10: =Восстановление!B36 -> Выполняется регулярное создание резервных копий в соответствии с регламентом | D10: =Восстановление!C36 -> ВССТ.ПЛН.5 | E10: =Восстановление!D36 -> 5 | F10: =Восстановление!E36 -> 3.2 | G10: =Восстановление!F36 -> 3.2 | H10: =Восстановление!S36 -> 22.05 | I10: =IF(H10<=200,"КБ1",IF(H10<=300,"КБ2","КБ3")) -> КБ1 | J10: =Восстановление!K36 -> 5 | K10: =Восстановление!I36 -> 0 | L10: =Восстановление!L36 -> 0 | M10: =IF(K10=J10," ",L10-K10) -> 0 | N10: =IF(H10<100,IF(L10>=G10,0,J10-L10),IF(H10<300,IF(L10>=F10,0,J10-L10),IF(L10>=E10,0,J10-L10))) -> 5 | O10: =Восстановление!T36 -> - Обеспечить регулярное создание резервных копий | P10: Заполнить | Q10: Выгрузка конфигураций ПО для резервного копирования/ скрипты - Снимки экрана мест хранения резервных копий - Скан-копия договора о предоставлении услуги резервного копирования / Электронная версия договора с реквизитами ЭП | T10: Не готово | U10: 0 | V10: 0 | W10: 0 | X10: =SUM(U10:W10) -> 0
A11: Восстановление | B11: Планирование восстановления | C11: =Восстановление!B37 -> Резервные копии хранятся на сторонних площадках | D11: =Восстановление!C37 -> ВССТ.ПЛН.6 | E11: =Восстановление!D37 -> 5 | F11: =Восстановление!E37 -> 3.2 | G11: =Восстановление!F37 -> 1.6 | H11: =Восстановление!S37 -> 22.06 | I11: =IF(H11<=200,"КБ1",IF(H11<=300,"КБ2","КБ3")) -> КБ1 | J11: =Восстановление!K37 -> 5 | K11: =Восстановление!I37 -> 0 | L11: =Восстановление!L37 -> 0 | M11: =IF(K11=J11," ",L11-K11) -> 0 | N11: =IF(H11<100,IF(L11>=G11,0,J11-L11),IF(H11<300,IF(L11>=F11,0,J11-L11),IF(L11>=E11,0,J11-L11))) -> 5 | O11: =Восстановление!T37 -> - Обеспечить хранение резервных копий вне площадки расположения ИА | P11: Заполнить | Q11: Выгрузка конфигураций ПО для резервного копирования/ скрипты - Снимки экрана мест хранения резервных копий - Скан-копия договора о предоставлении услуги резервного копирования / Электронная версия договора с реквизитами ЭП | T11: Не готово | U11: 0 | V11: 0 | W11: 0 | X11: =SUM(U11:W11) -> 0
A12: Восстановление | B12: Планирование восстановления | C12: =Восстановление!B38 -> Определены требования восстановления и проводятся тестирования | D12: =Восстановление!C38 -> ВССТ.ПЛН.7 | E12: =Восстановление!D38 -> 5 | F12: =Восстановление!E38 -> 3.2 | G12: =Восстановление!F38 -> 1.6 | H12: =Восстановление!S38 -> 22.07 | I12: =IF(H12<=200,"КБ1",IF(H12<=300,"КБ2","КБ3")) -> КБ1 | J12: =Восстановление!K38 -> 5 | K12: =Восстановление!I38 -> 0 | L12: =Восстановление!L38 -> 0 | M12: =IF(K12=J12," ",L12-K12) -> 0 | N12: =IF(H12<100,IF(L12>=G12,0,J12-L12),IF(H12<300,IF(L12>=F12,0,J12-L12),IF(L12>=E12,0,J12-L12))) -> 5 | O12: =Восстановление!T38 -> -Разработать и протестировать планы восстановления | P12: Заполнить | Q12: 1. Формализованный план восстановления 2.Отчет о проведенном тестировании | T12: Не готово | U12: 0 | V12: 0 | W12: 0 | X12: =SUM(U12:W12) -> 0
A13: Восстановление | B13: Планирование восстановления | C13: =Восстановление!B39 -> Тестирование планов по реагированию и восстановлению проводятся совместно с поставщиками и сторонними провайдерами (имеющими доступ в инфраструктуру Общества) | D13: =Восстановление!C39 -> ВССТ.ПЛН.8 | E13: =Восстановление!D39 -> 5 | F13: =Восстановление!E39 -> 3.2 | G13: =Восстановление!F39 -> 1.6 | H13: =Восстановление!S39 -> 22.08 | I13: =IF(H13<=200,"КБ1",IF(H13<=300,"КБ2","КБ3")) -> КБ1 | J13: =Восстановление!K39 -> 5 | K13: =Восстановление!I39 -> 0 | L13: =Восстановление!L39 -> 0 | M13: =IF(K13=J13," ",L13-K13) -> 0 | N13: =IF(H13<100,IF(L13>=G13,0,J13-L13),IF(H13<300,IF(L13>=F13,0,J13-L13),IF(L13>=E13,0,J13-L13))) -> 5 | O13: =Восстановление!T39 -> - Включить в договоры обязательства поставщика содействовать при проведении восстановительных мероприятий/ Определить SLA; - Определить ответственных за взаимодействие и их полномочия. | P13: Заполнить | Q13: 1. Формализованные требования к договорам с поставщиками услуг | T13: Не готово | U13: 0 | V13: 0 | W13: 0 | X13: 0
A14: Восстановление | B14: Планирование восстановления | C14: =Восстановление!B40 -> Планы восстановления совершенствуются по результатам тестирования и реагирования | D14: =Восстановление!C40 -> ВССТ.ПЛН.9 | E14: =Восстановление!D40 -> 5 | F14: =Восстановление!E40 -> 3.2 | G14: =Восстановление!F40 -> 1.6 | H14: =Восстановление!S40 -> 22.09 | I14: =IF(H14<=200,"КБ1",IF(H14<=300,"КБ2","КБ3")) -> КБ1 | J14: =Восстановление!K40 -> 5 | K14: =Восстановление!I40 -> 0 | L14: =Восстановление!L40 -> 0 | M14: =IF(K14=J14," ",L14-K14) -> 0 | N14: =IF(H14<100,IF(L14>=G14,0,J14-L14),IF(H14<300,IF(L14>=F14,0,J14-L14),IF(L14>=E14,0,J14-L14))) -> 5 | O14: =Восстановление!T40 -> - Проводить анализ результатов тестирования планов восстановления. Фиксировать отклонения от планов. | P14: Заполнить | Q14: 1. Справки/аналитические записки, материалы/служебные записки | T14: Не готово | U14: 0 | V14: 0 | W14: 0 | X14: =SUM(U14:W14) -> 0
A15: Нормативное соответствие | B15: 250 Указ | C15: ='250'!B53 -> Подготовлено и утверждено положение о заместителе, ответственном за обеспечение ИБ, в соответствии с требованиями Постановления Правительства РФ от 15.07.2022 № 1272 | D15: ='250'!C53 -> НС.250.ОУ.2 | E15: ='250'!D53 -> 5 | F15: ='250'!E53 -> 5 | G15: ='250'!F53 -> 5 | H15: ='Нормативное соответствие'!S111 -> 9.01 | I15: =IF(H15<=200, "КБ1", IF(H15<=300, "КБ2", "КБ3")) -> КБ1 | J15: ='250'!K53 -> 5 | K15: ='250'!I53 -> 0 | L15: ='250'!L53 -> 0 | M15: =IF(K15=J15," ",L15-K15) -> 0 | N15: =IF(H15<100, IF(L15>=G15,0,J15-L15), IF(H15<300, IF(L15>=F15,0,J15-L15), IF(L15>=E15,0,J15-L15))) -> 5 | O15: ='250'!S53 -> - Разработать и утвердить положение о заместителе, ответсвенном за обеспечение ИБ - Ознакомить с положением заместителя, ответственного за обеспечение ИБ | P15: Заполнить | Q15: 1. Утвержденное положение о заместителе, ответственном за обеспечение ИБ в соответствии с Постановлением Правительства РФ от 15.07.2022 № 1272 2. Листы ознакомления | T15: Не готово | U15: 0 | V15: 0 | W15: 0 | X15: =SUM(U15:W15) -> 0
A16: Нормативное соответствие | B16: 250 Указ | C16: ='250'!B54 -> Заместитель по ИБ входит в состав коллегиальных органов Общества | D16: ='250'!C54 -> НС.250.ОУ.3 | E16: ='250'!D54 -> 5 | F16: ='250'!E54 -> 5 | G16: ='250'!F54 -> 5 | H16: ='Нормативное соответствие'!S111 -> 9.01 | I16: =IF(H16<=200, "КБ1", IF(H16<=300, "КБ2", "КБ3")) -> КБ1 | J16: ='250'!K54 -> 5 | K16: ='250'!I54 -> 0 | L16: ='250'!L54 -> 0 | M16: =IF(K16=J16," ",L16-K16) -> 0 | N16: =IF(H16<100, IF(L16>=G16,0,J16-L16), IF(H16<300, IF(L16>=F16,0,J16-L16), IF(L16>=E16,0,J16-L16))) -> 5 | O16: ='250'!S54 -> - При наличии коллегиальных органов (правление, совет директоров) возложить полномочия ответственного за обеспечение ИБ на руководителя, входящего в состав указанных коллегиальных органов или включить ответственного за обеспечение ИБ в их состав. | P16: Заполнить | Q16: Предусмотрено в типовом Положении о заместителе руководителя организации, ответственном за обеспечение ИБ в соответствии с Постановлением Правительства РФ от 15.07.2022 № 1272. | T16: Не готово | U16: 0 | V16: 0 | W16: 0 | X16: =SUM(U16:W16) -> 0
A17: Нормативное соответствие | B17: 250 Указ | C17: ='250'!B55 -> Проводится обучение пользователей по ИБ | D17: ='250'!C55 -> НС.250.ОУ.4 | E17: ='250'!D55 -> 5 | F17: ='250'!E55 -> 5 | G17: ='250'!F55 -> 5 | H17: ='Нормативное соответствие'!S111 -> 9.01 | I17: =IF(H17<=200, "КБ1", IF(H17<=300, "КБ2", "КБ3")) -> КБ1 | J17: ='250'!K55 -> 5 | K17: ='250'!I55 -> 0 | L17: ='250'!L55 -> 0 | M17: =IF(K17=J17," ",L17-K17) -> 0 | N17: =IF(H17<100, IF(L17>=G17,0,J17-L17), IF(H17<300, IF(L17>=F17,0,J17-L17), IF(L17>=E17,0,J17-L17))) -> 5 | O17: ='250'!S55 -> - Разработать и утвердить правила и процедуры информирования и обучения персонала; - Переодически проводить обучение персонала правилам эксплуатации отдельных средств защиты информации, включая проведение практических занятий с персоналом; - Проводить контроль осведомленности персонала об угрозах безопасности информации и уровня знаний персонала по вопросам обеспечения ИБ - Актуализировать правила и процедуры информирования и обучения персонала | P17: Заполнить | Q17: 1) Разработанный внутренний нормативный документ: "Положение о повышении осведомленности работников"; 2) Организация рассылок работникам Общества с наиболее актуальной информацией в области информационной безопасности (угрозы информационной безопасности, схемы мошенничества, правила безопасной работы); 3) Организация обучения работников в очной/заочной форме (например, онлайн курсы с последующим тестированием знаний) | T17: Не готово | U17: 0 | V17: 0 | W17: 0 | X17: =SUM(U17:W17) -> 0
A18: Нормативное соответствие | B18: 250 Указ | C18: ='250'!B56 -> Заместитель руководителя Общества имеет необходимое обучение | D18: ='250'!C56 -> НС.250.ОУ.5 | E18: ='250'!D56 -> 5 | F18: ='250'!E56 -> 5 | G18: ='250'!F56 -> 5 | H18: ='Нормативное соответствие'!S111 -> 9.01 | I18: =IF(H18<=200, "КБ1", IF(H18<=300, "КБ2", "КБ3")) -> КБ1 | J18: ='250'!K56 -> 5 | K18: ='250'!I56 -> 0 | L18: ='250'!L56 -> 0 | M18: =IF(K18=J18," ",L18-K18) -> 0 | N18: =IF(H18<100, IF(L18>=G18,0,J18-L18), IF(H18<300, IF(L18>=F18,0,J18-L18), IF(L18>=E18,0,J18-L18))) -> 5 | O18: ='250'!S56 -> - Ответственное лицо должно иметь высшее образование (не ниже уровня специалитета, магистратуры) по направлению обеспечения информационной безопасности (далее – ИБ): ­ 10.0 - 01 «Информационная безопасность»; ­ 10.0 - 01 «Компьютерная безопасность»; ­ 10.0 - 02 «ИБ телекоммуникационных систем»; ­ 10.0 - 03 «ИБ автоматизированных систем»; ­ 10.0 - 04 «Информационно-аналитические системы безопасности»; ­ 10.0 - 05 «Безопасность ИТ в правоохранительных органах». Если ответственное лицо имеет высшее образование по другому направлению подготовки (специальности), то ответственное лицо обязано пройти обучение по программе профессиональной переподготовки по направлению 'Информационная безопасность'. Минимальный срок профессиональной переподготовки — 250 академических часов. | P18: Заполнить | Q18: Скан-копия диплома/свидетельства о переподготовке | T18: Не готово | U18: 0 | V18: 0 | W18: 0 | X18: =SUM(U18:W18) -> 0
A19: Нормативное соответствие | B19: 250 Указ | C19: ='250'!B57 -> Заместитель руководителя Общества проходит регулярное повышение квалификации | D19: ='250'!C57 -> НС.250.ОУ.6 | E19: ='250'!D57 -> 5 | F19: ='250'!E57 -> 5 | G19: ='250'!F57 -> 5 | H19: ='Нормативное соответствие'!S111 -> 9.01 | I19: =IF(H19<=200, "КБ1", IF(H19<=300, "КБ2", "КБ3")) -> КБ1 | J19: ='250'!K57 -> 5 | K19: ='250'!I57 -> 0 | L19: ='250'!L57 -> 0 | M19: =IF(K19=J19," ",L19-K19) -> 0 | N19: =IF(H19<100, IF(L19>=G19,0,J19-L19), IF(H19<300, IF(L19>=F19,0,J19-L19), IF(L19>=E19,0,J19-L19))) -> 5 | O19: ='250'!S57 -> - Ответственное лицо обязано проходит повышение квалификации не менее одного раза в 3 года | P19: Заполнить | Q19: Скан-копии свидетельств о повышении квалификации | T19: Не готово | U19: 0 | V19: 0 | W19: 0 | X19: =SUM(U19:W19) -> 0
A20: Нормативное соответствие | B20: 250 Указ | C20: ='250'!B58 -> Документы по цифровой трансформации и т.п проходят согласование с ИБ | D20: ='250'!C58 -> НС.250.ОУ.7 | E20: ='250'!D58 -> 5 | F20: ='250'!E58 -> 5 | G20: ='250'!F58 -> 5 | H20: ='Нормативное соответствие'!S111 -> 9.01 | I20: =IF(H20<=200, "КБ1", IF(H20<=300, "КБ2", "КБ3")) -> КБ1 | J20: ='250'!K58 -> 5 | K20: ='250'!I58 -> 0 | L20: ='250'!L58 -> 0 | M20: =IF(K20=J20," ",L20-K20) -> 0 | N20: =IF(H20<100, IF(L20>=G20,0,J20-L20), IF(H20<300, IF(L20>=F20,0,J20-L20), IF(L20>=E20,0,J20-L20))) -> 5 | O20: ='250'!S58 -> - Основополагающие документы Общества в сфере ИТ, цифровизации и цифровой трансформации должны быть согласованы с заместителем руководителя, ответственным за обеспечение ИБ | P20: Заполнить | Q20: Скан-копии ВНД и листов согласования/выгрузка и системы ЭД | T20: Не готово | U20: 0 | V20: 0 | W20: 0 | X20: =SUM(U20:W20) -> 0
A21: Нормативное соответствие | B21: 250 Указ | C21: ='250'!B59 -> Проводится регулярное повышение осведомленности | D21: ='250'!C59 -> НС.250.ОУ.8 | E21: ='250'!D59 -> 5 | F21: ='250'!E59 -> 5 | G21: ='250'!F59 -> 5 | H21: ='Нормативное соответствие'!S111 -> 9.01 | I21: =IF(H21<=200, "КБ1", IF(H21<=300, "КБ2", "КБ3")) -> КБ1 | J21: ='250'!K59 -> 5 | K21: ='250'!I59 -> 0 | L21: ='250'!L59 -> 0 | M21: =IF(K21=J21," ",L21-K21) -> 0 | N21: =IF(H21<100, IF(L21>=G21,0,J21-L21), IF(H21<300, IF(L21>=F21,0,J21-L21), IF(L21>=E21,0,J21-L21))) -> 5 | O21: ='250'!S59 -> - Наладить регулярное информирование руководства Общества о компьютерных инцидентах и текущем уровне ИБ в Общества. | P21: Заполнить | Q21: Ежегодный отчёт руководству Общества (в рамках отчёта по ежегодному Плану мероприятий. | T21: Не готово | U21: 0 | V21: 0 | W21: 0 | X21: =SUM(U21:W21) -> 0
A22: Нормативное соответствие | B22: 250 Указ | C22: ='250'!B62 -> Утверждено положение о подразделении, обеспечивающим ИБ в соответствии с требованиями Постановления Правительства РФ от 15.07.2022 № 1272 | D22: ='250'!C62 -> НС.250.ПДР.2 | E22: ='250'!D62 -> 5 | F22: ='250'!E62 -> 5 | G22: ='250'!F62 -> 5 | H22: ='Нормативное соответствие'!S112 -> 9.02 | I22: =IF(H22<=200, "КБ1", IF(H22<=300, "КБ2", "КБ3")) -> КБ1 | J22: ='250'!K62 -> 5 | K22: ='250'!I62 -> 0 | L22: ='250'!L62 -> 0 | M22: =IF(K22=J22," ",L22-K22) -> 0 | N22: =IF(H22<100, IF(L22>=G22,0,J22-L22), IF(H22<300, IF(L22>=F22,0,J22-L22), IF(L22>=E22,0,J22-L22))) -> 5 | O22: ='250'!S62 -> - Разработать и утвердить положение о структурном подразделении, ответсвенном за обеспечение ИБ - Ознакомить с положением подразделение, ответственное за обеспечение ИБ | P22: Заполнить | Q22: Утвержденное положение о структурном подразделении, ответственном за обеспечение ИБ, в соответствии с требованиями ПП от 15.07.2022 № 1272 | T22: Не готово | U22: 0 | V22: 0 | W22: 0 | X22: =SUM(U22:W22) -> 0
A23: Нормативное соответствие | B23: 250 Указ | C23: ='250'!B63 -> Подразделение подчинено заместителю руководителю Общества, ответственному за ИБ | D23: ='250'!C63 -> НС.250.ПДР.3 | E23: ='250'!D63 -> 5 | F23: ='250'!E63 -> 5 | G23: ='250'!F63 -> 5 | H23: ='Нормативное соответствие'!S112 -> 9.02 | I23: =IF(H23<=200, "КБ1", IF(H23<=300, "КБ2", "КБ3")) -> КБ1 | J23: ='250'!K62 -> 5 | K23: ='250'!I63 -> 0 | L23: ='250'!L63 -> 0 | M23: =IF(K23=J23," ",L23-K23) -> 0 | N23: =IF(H23<100, IF(L23>=G23,0,J23-L23), IF(H23<300, IF(L23>=F23,0,J23-L23), IF(L23>=E23,0,J23-L23))) -> 5 | O23: ='250'!S63 -> - Подчинить подразделение, ответственное за обеспечение ИБ, заместителю руководителю Общества, ответственному за ИБ, в соответствии со орг. структурой Общества | P23: Заполнить | Q23: Утвержденное положение о структурном подразделении, ответственном за обеспечение ИБ, в соответствии с требованиями ПП от 15.07.2022 № 1272 | T23: Не готово | U23: 0 | V23: 0 | W23: 0 | X23: =SUM(U23:W23) -> 0
A24: Нормативное соответствие | B24: 250 Указ | C24: ='250'!B65 -> Все привлекаемые к осуществлению мероприятий по ИБ организации имеют лицензии | D24: ='250'!C65 -> НС.250.ПДРД.1 | E24: ='250'!D65 -> 5 | F24: ='250'!E65 -> 5 | G24: ='250'!F65 -> 5 | H24: ='Нормативное соответствие'!S113 -> 9.03 | I24: =IF(H24<=200, "КБ1", IF(H24<=300, "КБ2", "КБ3")) -> КБ1 | J24: ='250'!K65 -> 5 | K24: ='250'!I65 -> 0 | L24: ='250'!L65 -> 0 | M24: =IF(K24=J24," ",L24-K24) -> 0 | N24: =IF(H24<100, IF(L24>=G24,0,J24-L24), IF(H24<300, IF(L24>=F24,0,J24-L24), IF(L24>=E24,0,J24-L24))) -> 5 | O24: ='250'!S65 -> - Привлекать к мероприятиям по ИБ только организации имеющие лицензии ФСТЭК и ФСБ | P24: Заполнить | Q24: Скан-копии договоров с подрядчиками, скан-копии лицензий | T24: Не готово | U24: 0 | V24: 0 | W24: 0 | X24: =SUM(U24:W24) -> 0
A25: Нормативное соответствие | B25: 250 Указ | C25: ='250'!B66 -> Привлекаемый SOC имеет аккредитацию | D25: ='250'!C66 -> НС.250.ПДРД.2 | E25: ='250'!D66 -> 5 | F25: ='250'!E66 -> 5 | G25: ='250'!F66 -> 5 | H25: ='Нормативное соответствие'!S113 -> 9.03 | I25: =IF(H25<=200, "КБ1", IF(H25<=300, "КБ2", "КБ3")) -> КБ1 | J25: ='250'!K66 -> 5 | K25: ='250'!I66 -> 0 | L25: ='250'!L66 -> 0 | M25: =IF(K25=J25," ",L25-K25) -> 0 | N25: =IF(H25<100, IF(L25>=G25,0,J25-L25), IF(H25<300, IF(L25>=F25,0,J25-L25), IF(L25>=E25,0,J25-L25))) -> 5 | O25: ='250'!S66 -> - При заключении договора с SOC убедиться в наличии аккредитации | P25: Заполнить | Q25: Скан-копия договора на предоставление услуг SOC | T25: Не готово | U25: 0 | V25: 0 | W25: 0 | X25: =SUM(U25:W25) -> 0
A26: Нормативное соответствие | B26: 250 Указ | C26: ='250'!B67 -> Привлекаемые для оценки защищенности организации имеют лицензию ФСТЭК | D26: ='250'!C67 -> НС.250.ПДРД.3 | E26: ='250'!D67 -> 5 | F26: ='250'!E67 -> 5 | G26: ='250'!F67 -> 5 | H26: ='Нормативное соответствие'!S113 -> 9.03 | I26: =IF(H26<=200, "КБ1", IF(H26<=300, "КБ2", "КБ3")) -> КБ1 | J26: ='250'!K67 -> 5 | K26: ='250'!I67 -> 0 | L26: ='250'!L67 -> 0 | M26: =IF(K26=J26," ",L26-K26) -> 0 | N26: =IF(H26<100, IF(L26>=G26,0,J26-L26), IF(H26<300, IF(L26>=F26,0,J26-L26), IF(L26>=E26,0,J26-L26))) -> 5 | O26: ='250'!S67 -> - Определить и привлечь организацию для оценки уровня защищенности информационных систем ,имеющих соответствующие лицензии ФСТЭК и ФСБ (https://reestr.fstec.ru/reg1). - Сформировать техническое задание на выполнение работ по оценке уровня защищенности. - Получить отчетные документы в бумажном и в электронном виде от лицензиата по результатам оценки уровня защищенности информационных систем. - На основании распоряжения Правительства РФ от 2 - 0 - 2022 N 1661-р (ред. от 0 - 0 - 2023) 'Об утверждении перечня ключевых органов (организаций), которым необходимо осуществить мероприятия по оценке уровня защищенности своих информационных систем с привлечением организаций, имеющих соответствующие лицензии ФСБ России и ФСТЭК Росси' предоставить отчетные документы по оценке уровня защищенности информационных систем Правительству РФ, а также в адрес ФСТЭК и ФСБ России на основании соответствующего запроса. | P26: Заполнить | Q26: Скан-копия договора с подрядчиком, скан копия лицензии | T26: Не готово | U26: 0 | V26: 0 | W26: 0 | X26: =SUM(U26:W26) -> 0
A27: Нормативное соответствие | B27: 250 Указ | C27: ='250'!B68 -> Привлекаемые для оценки защищенности организации имеют лицензию ФСБ | D27: ='250'!C68 -> НС.250.ПДРД.4 | E27: ='250'!D68 -> 5 | F27: ='250'!E68 -> 5 | G27: ='250'!F68 -> 5 | H27: ='Нормативное соответствие'!S113 -> 9.03 | I27: =IF(H27<=200, "КБ1", IF(H27<=300, "КБ2", "КБ3")) -> КБ1 | J27: ='250'!K68 -> 5 | K27: ='250'!I68 -> 0 | L27: ='250'!L68 -> 0 | M27: =IF(K27=J27," ",L27-K27) -> 0 | N27: =IF(H27<100, IF(L27>=G27,0,J27-L27), IF(H27<300, IF(L27>=F27,0,J27-L27), IF(L27>=E27,0,J27-L27))) -> 5 | O27: ='250'!S68 -> - Определить и привлечь организацию для оценки уровня защищенности информационных систем ,имеющих соответствующие лицензии ФСТЭК и ФСБ (https://reestr.fstec.ru/reg1). - Сформировать техническое задание на выполнение работ по оценке уровня защищенности. - Получить отчетные документы в бумажном и в электронном виде от лицензиата по результатам оценки уровня защищенности информационных систем. - На основании распоряжения Правительства РФ от 2 - 0 - 2022 N 1661-р (ред. от 0 - 0 - 2023) 'Об утверждении перечня ключевых органов (организаций), которым необходимо осуществить мероприятия по оценке уровня защищенности своих информационных систем с привлечением организаций, имеющих соответствующие лицензии ФСБ России и ФСТЭК Росси' предоставить отчетные документы по оценке уровня защищенности информационных систем Правительству РФ, а также в адрес ФСТЭК и ФСБ России на основании соответствующего запроса. | P27: Заполнить | Q27: Скан-копия договора с подрядчиком, скан копия лицензии | T27: Не готово | U27: 0 | V27: 0 | W27: 0 | X27: =SUM(U27:W27) -> 0
A28: Нормативное соответствие | B28: 250 Указ | C28: ='250'!B70 -> Произведена инвентаризация СЗИ на предмет выявления импортного | D28: ='250'!C70 -> НС.250.СЗИ.1 | E28: ='250'!D70 -> 5 | F28: ='250'!E70 -> 5 | G28: ='250'!F70 -> 5 | H28: ='Нормативное соответствие'!S114 -> 9.04 | I28: =IF(H28<=200,"КБ1",IF(H28<=300,"КБ2","КБ3")) -> КБ1 | J28: ='250'!K70 -> 5 | K28: ='250'!I70 -> 0 | L28: ='250'!L70 -> 0 | M28: =IF(K28=J28," ",L28-K28) -> 0 | N28: =IF(H28<100,IF(L28>=G28,0,J28-L28),IF(H28<300,IF(L28>=F28,0,J28-L28),IF(L28>=E28,0,J28-L28))) -> 5 | O28: ='250'!S70 -> - Провести инвентаризацию используемых средств защиты информации и выявить все средства из недружественных государств | P28: Заполнить | Q28: Перечень используемых средств защиты информации из недружественных государств | T28: Не готово | U28: 0 | V28: 0 | W28: 0 | X28: =SUM(U28:W28) -> 0
A29: Нормативное соответствие | B29: 250 Указ | C29: ='250'!B71 -> Проведена оценка возможности перехода на отечественное | D29: ='250'!C71 -> НС.250.СЗИ.2 | E29: ='250'!D71 -> 5 | F29: ='250'!E71 -> 5 | G29: ='250'!F71 -> 5 | H29: ='Нормативное соответствие'!S114 -> 9.04 | I29: =IF(H29<=200,"КБ1",IF(H29<=300,"КБ2","КБ3")) -> КБ1 | J29: ='250'!K71 -> 5 | K29: ='250'!I71 -> 0 | L29: ='250'!L71 -> 0 | M29: =IF(K29=J29," ",L29-K29) -> 0 | N29: =IF(H29<100,IF(L29>=G29,0,J29-L29),IF(H29<300,IF(L29>=F29,0,J29-L29),IF(L29>=E29,0,J29-L29))) -> 5 | O29: ='250'!S71 -> - Провести оценку возможности перехода с используемых средств защиты информации из недружественных государств на иные решения (отечественные, open source или из дружественных государств). | P29: Заполнить | Q29: Результат анализа возможности перехода | T29: Не готово | U29: 0 | V29: 0 | W29: 0 | X29: =SUM(U29:W29) -> 0
A30: Нормативное соответствие | B30: 250 Указ | C30: ='250'!B72 -> Подготовлен план перехода | D30: ='250'!C72 -> НС.250.СЗИ.3 | E30: ='250'!D72 -> 5 | F30: ='250'!E72 -> 5 | G30: ='250'!F72 -> 5 | H30: ='Нормативное соответствие'!S114 -> 9.04 | I30: =IF(H30<=200,"КБ1",IF(H30<=300,"КБ2","КБ3")) -> КБ1 | J30: ='250'!K72 -> 5 | K30: ='250'!I72 -> 0 | L30: ='250'!L72 -> 0 | M30: =IF(K30=J30," ",L30-K30) -> 0 | N30: =IF(H30<100,IF(L30>=G30,0,J30-L30),IF(H30<300,IF(L30>=F30,0,J30-L30),IF(L30>=E30,0,J30-L30))) -> 5 | O30: ='250'!S72 -> - Подготовить план перехода со средств защиты информации из недружественных государств. | P30: Заполнить | Q30: Утвержденный План перехода | T30: Не готово | U30: 0 | V30: 0 | W30: 0 | X30: =SUM(U30:W30) -> 0
A31: Нормативное соответствие | B31: 250 Указ | C31: ='250'!B73 -> Осуществлено пилотирование | D31: ='250'!C73 -> НС.250.СЗИ.4 | E31: ='250'!D73 -> 5 | F31: ='250'!E73 -> 5 | G31: ='250'!F73 -> 5 | H31: ='Нормативное соответствие'!S114 -> 9.04 | I31: =IF(H31<=200,"КБ1",IF(H31<=300,"КБ2","КБ3")) -> КБ1 | J31: ='250'!K73 -> 5 | K31: ='250'!I73 -> 0 | L31: ='250'!L73 -> 0 | M31: =IF(K31=J31," ",L31-K31) -> 0 | N31: =IF(H31<100,IF(L31>=G31,0,J31-L31),IF(H31<300,IF(L31>=F31,0,J31-L31),IF(L31>=E31,0,J31-L31))) -> 5 | O31: ='250'!S73 -> - Осуществить пилотирование решений, выбранных для замены средствам защиты информации из недружественных государств | P31: Заполнить | Q31: Документ по результатам проведения пилотирования | T31: Не готово | U31: 0 | V31: 0 | W31: 0 | X31: =SUM(U31:W31) -> 0
A32: Нормативное соответствие | B32: 250 Указ | C32: ='250'!B74 -> Сделан выбор и осуществлено внедрение выбранного СЗИ | D32: ='250'!C74 -> НС.250.СЗИ.5 | E32: ='250'!D74 -> 5 | F32: ='250'!E74 -> 5 | G32: ='250'!F74 -> 5 | H32: ='Нормативное соответствие'!S114 -> 9.04 | I32: =IF(H32<=200,"КБ1",IF(H32<=300,"КБ2","КБ3")) -> КБ1 | J32: ='250'!K74 -> 5 | K32: ='250'!I74 -> 0 | L32: ='250'!L74 -> 0 | M32: =IF(K32=J32," ",L32-K32) -> 0 | N32: =IF(H32<100,IF(L32>=G32,0,J32-L32),IF(H32<300,IF(L32>=F32,0,J32-L32),IF(L32>=E32,0,J32-L32))) -> 5 | O32: ='250'!S74 -> - Внедрить выбранные средства защиты информации. | P32: Заполнить | Q32: Утвержденный Акт ввода в эксплуатацию средств защиты информации. | T32: Не готово | U32: 0 | V32: 0 | W32: 0 | X32: =SUM(U32:W32) -> 0
A33: Нормативное соответствие | B33: 250 Указ | C33: ='250'!B76 -> Утвержден регламент взаимодействия с ГосСОПКА | D33: ='250'!C76 -> НС.250.СОПКА.1 | E33: ='250'!D76 -> 5 | F33: ='250'!E76 -> 5 | G33: ='250'!F76 -> 5 | H33: ='Нормативное соответствие'!S115 -> 9.05 | I33: =IF(H33<=200,"КБ1",IF(H33<=300,"КБ2","КБ3")) -> КБ1 | J33: ='250'!K76 -> 5 | K33: ='250'!I76 -> 0 | L33: ='250'!L76 -> 0 | M33: =IF(K33=J33," ",L33-K33) -> 0 | N33: =IF(H33<100,IF(L33>=G33,0,J33-L33),IF(H33<300,IF(L33>=F33,0,J33-L33),IF(L33>=E33,0,J33-L33))) -> 5 | O33: ='250'!S76 -> - Подписать Соглашение о взаимодействии Публичного акционерного общества Ростелеком и ДЗО в области обнаружения, предупреждения и ликвидации последствий компьютерных атак ; - Разработать и утверждить ОРД и ВНД, регламентирующие взаимодействие с Корпоративным центром ГосСОПКА (на базе SOC Департамент мониторинга и реагирования на компьютерные инциденты КЦ ПАО 'Ростелеком; далее - КЦ ГосСОПКА): - утвердить регламент информирования ФСБ России (НКЦКИ) о компьютерных инцидентах; - Утвердить перечень информации о компьютерных инцидентах, связанных с функционированием объектов КИИ; - Разработать и утвердить правила и процедуры реагирования на компьютерные инциденты. | P33: Заполнить | Q33: Соглашение между ПАО "Ростелеком" и ДЗО в области обнаружения, предупреждения и ликвидации последствий компьютерных атак Утвержденный набор ВНД и ОРД | T33: Не готово | U33: 0 | V33: 0 | W33: 0 | X33: =SUM(U33:W33) -> 0
A34: Нормативное соответствие | B34: 250 Указ | C34: ='250'!B77 -> Осуществляется мониторинг ресурсов | D34: ='250'!C77 -> НС.250.СОПКА.2 | E34: ='250'!D77 -> 5 | F34: ='250'!E77 -> 5 | G34: ='250'!F77 -> 5 | H34: ='Нормативное соответствие'!S115 -> 9.05 | I34: =IF(H34<=200,"КБ1",IF(H34<=300,"КБ2","КБ3")) -> КБ1 | J34: ='250'!K77 -> 5 | K34: ='250'!I77 -> 0 | L34: ='250'!L77 -> 0 | M34: =IF(K34=J34," ",L34-K34) -> 0 | N34: =IF(H34<100,IF(L34>=G34,0,J34-L34),IF(H34<300,IF(L34>=F34,0,J34-L34),IF(L34>=E34,0,J34-L34))) -> 5 | O34: ='250'!S77 -> - Выполнить подключение ЗОКИИ к КЦ ГосСОПКА - Организовать двустороннее взаимодействие с КЦ ГосСОПКА по мониторингу защищенности ЗОКИИ, принадлежащих Обществу или используемых ею | P34: Заполнить | Q34: Утвержденный Регламент взаимодействия с КЦ ГосСОПКА | T34: Не готово | U34: 0 | V34: 0 | W34: 0 | X34: =SUM(U34:W34) -> 0
A35: Нормативное соответствие | B35: 250 Указ | C35: ='250'!B78 -> Организовано взаимодействие с должностными лицами ФСБ России по результатам мониторинга | D35: ='250'!C78 -> НС.250.СОПКА.3 | E35: ='250'!D78 -> 5 | F35: ='250'!E78 -> 5 | G35: ='250'!F78 -> 5 | H35: ='Нормативное соответствие'!S115 -> 9.05 | I35: =IF(H35<=200,"КБ1",IF(H35<=300,"КБ2","КБ3")) -> КБ1 | J35: ='250'!K78 -> 5 | K35: ='250'!I78 -> 0 | L35: ='250'!L78 -> 0 | M35: =IF(K35=J35," ",L35-K35) -> 0 | N35: =IF(H35<100,IF(L35>=G35,0,J35-L35),IF(H35<300,IF(L35>=F35,0,J35-L35),IF(L35>=E35,0,J35-L35))) -> 5 | O35: ='250'!S78 -> - Запросить информацию у КЦ ГосСОПКА по поводу организации взаимодействия с должностными лицами ФСБ России и ее территориальных органов по результатам мониторинга защищенности информационных ресурсов Общества. | P35: Заполнить | Q35: Утвержденный Регламент информирования ФСБ России (НКЦКИ) о компьютерных инцидентах | T35: Не готово | U35: 0 | V35: 0 | W35: 0 | X35: =SUM(U35:W35) -> 0
A36: Нормативное соответствие | B36: 250 Указ | C36: ='250'!B79 -> Заключено соглашение с НКЦКИ | D36: ='250'!C79 -> НС.250.СОПКА.4 | E36: ='250'!D79 -> 5 | F36: ='250'!E79 -> 5 | G36: ='250'!F79 -> 5 | H36: ='Нормативное соответствие'!S115 -> 9.05 | I36: =IF(H36<=200,"КБ1",IF(H36<=300,"КБ2","КБ3")) -> КБ1 | J36: ='250'!K79 -> 5 | K36: ='250'!I79 -> 0 | L36: ='250'!L79 -> 0 | M36: =IF(K36=J36," ",L36-K36) -> 0 | N36: =IF(H36<100,IF(L36>=G36,0,J36-L36),IF(H36<300,IF(L36>=F36,0,J36-L36),IF(L36>=E36,0,J36-L36))) -> 5 | O36: ='250'!S79 -> - Запросить информацию у КЦ ГосСОПКА по поводу соглашения с НКЦКИ - Разработать и утвердить план реагирования на компьютерные инциденты и принятия мер по ликвидации последствий компьютерных атак самостоятельно или совместно с НКЦКИ. - Направить План на согласование в НКЦКИ | P36: Заполнить | Q36: Утвержденный План реагирования на компьютерные инциденты и принятия мер по ликвидации последствий компьютерных атак | T36: Не готово | U36: 0 | V36: 0 | W36: 0 | X36: =SUM(U36:W36) -> 0
A37: Нормативное соответствие | B37: 250 Указ | C37: ='250'!B80 -> Организовано взаимодействие с НКЦКИ | D37: ='250'!C80 -> НС.250.СОПКА.5 | E37: ='250'!D80 -> 5 | F37: ='250'!E80 -> 5 | G37: ='250'!F80 -> 5 | H37: ='Нормативное соответствие'!S115 -> 9.05 | I37: =IF(H37<=200,"КБ1",IF(H37<=300,"КБ2","КБ3")) -> КБ1 | J37: ='250'!K80 -> 5 | K37: ='250'!I80 -> 0 | L37: ='250'!L80 -> 0 | M37: =IF(K37=J37," ",L37-K37) -> 0 | N37: =IF(H37<100,IF(L37>=G37,0,J37-L37),IF(H37<300,IF(L37>=F37,0,J37-L37),IF(L37>=E37,0,J37-L37))) -> 5 | O37: ='250'!S80 -> - Запросить информацию у КЦ ГосСОПКА по поводу организации взаимодействия с НКЦКИ - Уведомить НКЦКИ о передаче информации по компьютерным инцидентам через КЦ ГосСОПКА | P37: Заполнить | Q37: Письмо в адрес Директора НКЦКИ письмо о принятом решении информировать НКЦКИ через КЦ ГосСОПКА | T37: Не готово | U37: 0 | V37: 0 | W37: 0 | X37: =SUM(U37:W37) -> 0
A38: Нормативное соответствие | B38: КИИ | C38: ='Нормативное соответствие'!B75 -> Полномочия по обеспечению ИБ возложены на заместителя руководителя Общества | D38: ='Нормативное соответствие'!C75 -> НС.КИИ.1 | E38: ='Нормативное соответствие'!D75 -> 5 | F38: ='Нормативное соответствие'!E75 -> 5 | G38: ='Нормативное соответствие'!F75 -> 5 | H38: ='Нормативное соответствие'!S75 -> 8.01 | I38: =IF(H38<=200, "КБ1", IF(H38<=300, "КБ2", "КБ3")) -> КБ1 | J38: ='Нормативное соответствие'!K75 -> 5 | K38: ='Нормативное соответствие'!I75 -> 0 | L38: ='Нормативное соответствие'!L75 -> 0 | M38: =IF(K38=J38," ",L38-K38) -> 0 | N38: =IF(H38<100, IF(L38>=G38,0,J38-L38), IF(H38<300, IF(L38>=F38,0,J38-L38), IF(L38>=E38,0,J38-L38))) -> 5 | O38: ='Нормативное соответствие'!T75 -> - В соотвествии с приказом 235 с Приказом ФСТЭК от 21 декабря 2017 г. N 235 Об утверждении Требований к созданию систем безопасности значимых объектов критической информационной инфраструктуры Российской Федерации и обеспечению их функционирования: - Определить полномочия для подразделения, ответственное за ИБ (как минимум уровня отдела ИБ); - Подготовить положение о подразделении, обеспечивающим ИБ в Обществе; - Создать выделенное подразделение, ответственное за ИБ (как минимум уровня отдела ИБ): - Утвердить приказом по орг. структуре создание подразделения ИБ; - Утвердить положение о подразделении, обеспечивающим ИБ в Обществе; - Распоряжением/приказом определить подразделение ИБ, как подразделение Общества, ответственное за обеспечение безопасности значимых объектов КИИ; Если 2-3 работника подчиняются главному инженеру (тех. директору) или заместителю по безопасности (экономической и физической), то этих 2-3 работников необходимо выделить в отдельный отдел информационной безопасности. | P38: Заполнить | Q38: 1) Положение "О подразделении, обеспечивающем ИБ" в соответствии с Постановлением Правительства РФ от 15.07.2022 № 1272. 2) Приказ "О назначении ответственных за обеспечение безопасности значимых объектов критической информационной инфраструктуры"; 3) Приказ о создании отдельного структурного подразделение (СП) по ИБ или возложие функций по обеспечению ИБ на действующих работников СП по ИТ (при их отсутствии возложение обязанностей допустимо на иную техническую должность, приближенную к ИТ). | T38: Не готово | U38: 0 | V38: 0 | W38: 0 | X38: =SUM(U38:W38) -> 0
A39: Нормативное соответствие | B39: КИИ | C39: ='Нормативное соответствие'!B88 -> Взаимодействие с ГОССОПКА | D39: ='Нормативное соответствие'!C88 -> НС.КИИ.14 | E39: ='Нормативное соответствие'!D88 -> 5 | F39: ='Нормативное соответствие'!E88 -> 5 | G39: ='Нормативное соответствие'!F88 -> 5 | H39: ='Нормативное соответствие'!S88 -> 8.14 | I39: =IF(H39<=200, "КБ1", IF(H39<=300, "КБ2", "КБ3")) -> КБ1 | J39: ='Нормативное соответствие'!K88 -> 5 | K39: ='Нормативное соответствие'!I88 -> 0 | L39: ='Нормативное соответствие'!L88 -> 0 | M39: =IF(K39=J39," ",L39-K39) -> 0 | N39: =IF(H39<100, IF(L39>=G39,0,J39-L39), IF(H39<300, IF(L39>=F39,0,J39-L39), IF(L39>=E39,0,J39-L39))) -> 5 | O39: ='Нормативное соответствие'!T88 -> - Выполнить подключение ЗОКИИ к Корпоративному центру ГосСОПКА (на базе SOC Департамент мониторинга и реагирования на компьютерные инциденты КЦ ПАО Ростелеком; далее - КЦ ГосСОПКА): 1. Подписать Соглашение о взаимодействии Публичного акционерного общества Ростелеком и ДЗО в области обнаружения, предупреждения и ликвидации последствий компьютерных атак 2. Разработать и утвердить ОРД и ВНД, регламентирующие взаимодействие с КЦ ГосСОПКА: - утвердить регламент информирования ФСБ России (НКЦКИ) о компьютерных инцидентах; - Утвердить перечень информации о компьютерных инцидентах, связанных с функционированием объектов КИИ; - Разработать и утвердить правила и процедуры реагирования на компьютерные инциденты. - Разработать и утвердить план реагирования на компьютерные инциденты и принятия мер по ликвидации последствий компьютерных атак самостоятельно или совместно с НКЦКИ. - Направить План на согласование в НКЦКИ. | P39: Заполнить | Q39: 1) Скан договора на подключение к КЦ ГосСОПКА ПАО "Ростелеком" 2) Регламент взаимодействия с КЦ ГосСОПКА или 1) Соглашение с подписью сторон с НКЦКИ о взаимодействии в области обнаружения, предупреждения и ликвидации последствий компьютерных атак; 2) Утвержденный Регламент взаимодействия при осуществлении информационного обмена в области обнаружения, предупреждения и ликвидации последствий компьютерных атак. | T39: Не готово | U39: 0 | V39: 0 | W39: 0 | X39: =SUM(U39:W39) -> 0
A40: Нормативное соответствие | B40: КИИ | C40: ='Нормативное соответствие'!B89 -> Предоставлены своевременные ответы на запросы ФСТЭК России о выполнении мер по защите информации, рекомендованных к реализации (ответы предоставлены на более чем 95% запросов) | D40: ='Нормативное соответствие'!C89 -> НС.КИИ.15 | E40: ='Нормативное соответствие'!D89 -> 5 | F40: ='Нормативное соответствие'!E89 -> 5 | G40: ='Нормативное соответствие'!F89 -> 3.2 | H40: ='Нормативное соответствие'!S89 -> 8.15 | I40: =IF(H40<=200, "КБ1", IF(H40<=300, "КБ2", "КБ3")) -> КБ1 | J40: ='Нормативное соответствие'!K89 -> 5 | K40: ='Нормативное соответствие'!I89 -> 0 | L40: ='Нормативное соответствие'!L89 -> 0 | M40: =IF(K40=J40," ",L40-K40) -> 0 | N40: =IF(H40<100, IF(L40>=G40,0,J40-L40), IF(H40<300, IF(L40>=F40,0,J40-L40), IF(L40>=E40,0,J40-L40))) -> 5 | O40: ='Нормативное соответствие'!T89 -> - Определить ответственного сотрудника за взаимодействие с гос.регуляторами в области запросов КИИ | P40: Заполнить | Q40: ОРД с указанием ответственного работника за взаимодействие с гос.регуляторами в области запросов КИИ | T40: Не готово | U40: 0 | V40: 0 | W40: 0 | X40: =SUM(U40:W40) -> 0
...

