Workbook
Name БР: ИТОГ!$AA$34
Name ГИС: ИТОГ!$V$35
Name КИИ: ИТОГ!$V$36
Name КТ: ИТОГ!$V$40
Name ЛИЦ: ИТОГ!$V$34
Name Лицензия: ИТОГ!$V$34
Name ПДН: ИТОГ!$V$37
Name СКЗИ: ИТОГ!$AA$35
Name СКПДН: ИТОГ!$V$38
Name СТОРПДН: ИТОГ!$V$37
Name СУДПДН: ИТОГ!$V$39
Name ЦУКБ: ИТОГ!$L$3

Sheet Описание
D2: Индекс кибербезопаности
B10: Данный файл предназначен для проведения саммоценки состояния информационной безопасности и расчета итогового "Индекса кибербезопасности".
B13: Для работы с файлом необходимо заполнить данные в ячейках с желтым фоном на листах с зелеными ярлычками.
B14: На вкладке "ИТОГ" отображается сводный график достижения целевого уровня кибербезопасности.
B15: Лист "Расчет" - это итоговая служебная таблица, на которой осуществляется промежуточный расчет, он не предназначен для редактирования
B18: Рассчет индекса ведется как некоторая усредненная величина показателей по отдельным доменам кибербезопасности.
B19: В каждой отдельной вкладке доменеа строится своя диаграмма и рассчитывается свой локальный индекс.

Sheet ИТОГ
D2: Итоговый рассчетный индекс кибербезопасности и диаграмма достижения целевых показателей в различных доменах информационной безопасности | L2: Целевой уровень | O2: =Расчет!M3 -> 0.35251776 | U2: КБ1 | X2: КБ2 | AA2: КБ3
L3: КБ1 | O3: на | P3: =Расчет!M2 -> 46038 | R3: тренд | U3: =Расчет!T3 -> 0.28957767 | X3: =Расчет!S3 -> 0.093196018 | AA3: =Расчет!R3 -> 0.071458828
V8: =Светофор!F20 -> 0.15479231 | X8: - Предварительное значение оценки показателя состояния ТЗИ и обеспечения безопасности ЗОКИИ РФ в соответствии с Методикой ФСТЭК России
V12: =Светофор!J33 -> 0 | X12: - Отраслевой стандарт защиты данных
V34: нет | W34: Лицензиат ФСТЭК/ФСБ | AA34: да | AB34: Безопасная разработка
V35: да | W35: Наличие ГИС | AA35: да | AB35: СКЗИ ГОСТ
V36: нет | W36: Субьект КИИ
V37: нет | W37: Обработка сторонних ПДН
V38: нет | W38: Спец. Категории ПДН
V39: нет | W39: ПДН о судимости
V40: да | W40: Наличие Коммерческой тайны

Sheet Расчет
C1: КБ3 | D1: КБ2 | E1: КБ1 | F1: Исторические данные | H1: Исторические данные середину 2024 г. | I1: Исторические данные на конец 2024 г. | J1: Архивные расчетные данные на 31.12.2024 | K1: Расчетные данные на 31.12.2026 | L1: Расчетные данные на 31.12.2025 | M1: Текущий показатель | P1: Степень выполнения расчетного показателя | R1: Степень достижения КБ3 | S1: Степень достижения КБ2 | T1: Степень достижения КБ1
B2: Дата заполнения | F2: 45017 | G2: 45291 | H2: 45444 | M2: =TODAY() -> 46038
B3: ИНДЕКС КИБЕРБЕЗОПАСНОСТИ | C3: =0.3*( SUM(C23+C24+C25+C26+C27*IF(СКЗИ="да",1,0)) / (1+1+1+1+1*IF(СКЗИ="да",1,0)) ) +0.2*(SUM(C18+C19*IF(СКЗИ="да",1,0)+(C20+C21)*IF(КИИ="да",1,0)+C22*IF(КТ="да",1,0)) / (1+1*IF(СКЗИ="да",1,0)+(2)*IF(КИИ="да",1,0)+1*IF(КТ="да",1,0)) ) +0.3*(SUM(C4,C6,C28,C37,C38,C39)/6) +0.2*(SUM(C40:C45,C29:C36,C7:C15,C17,C5, C16*IF(БР="да",1,0)) / (25+1*IF(БР="да",1,0))) -> 4.8446459 | D3: =0.3*( SUM(D23+D24+D25+D26+D27*IF(СКЗИ="да",1,0)) / (1+1+1+1+1*IF(СКЗИ="да",1,0)) ) +0.2*(SUM(D18+D19*IF(СКЗИ="да",1,0)+(D20+D21)*IF(КИИ="да",1,0)+D22*IF(КТ="да",1,0)) / (1+1*IF(СКЗИ="да",1,0)+(2)*IF(КИИ="да",1,0)+1*IF(КТ="да",1,0)) ) +0.3*(SUM(D4,D6,D28,D37,D38,D39)/6) +0.2*(SUM(D40:D45,D29:D36,D7:D15,D17,D5, D16*IF(БР="да",1,0)) / (25+1*IF(БР="да",1,0))) -> 4.1010903 | E3: =0.3*( SUM(E23+E24+E25+E26+E27*IF(СКЗИ="да",1,0)) / (1+1+1+1+1*IF(СКЗИ="да",1,0)) ) +0.2*(SUM(E18+E19*IF(СКЗИ="да",1,0)+(E20+E21)*IF(КИИ="да",1,0)+E22*IF(КТ="да",1,0)) / (1+1*IF(СКЗИ="да",1,0)+(2)*IF(КИИ="да",1,0)+1*IF(КТ="да",1,0)) ) +0.3*(SUM(E4,E6,E28,E37,E38,E39)/6) +0.2*(SUM(E40:E45,E29:E36,E7:E15,E17,E5, E16*IF(БР="да",1,0)) / (25+1*IF(БР="да",1,0))) -> 2.5051598 | F3: =0.3*( SUM(F23+F24+F25+F26+F27*IF(СКЗИ="да",1,0)) / (1+1+1+1+1*IF(СКЗИ="да",1,0)) ) +0.2*(SUM(F18+F19*IF(СКЗИ="да",1,0)+(F20+F21)*IF(КИИ="да",1,0)+F22*IF(КТ="да",1,0)) / (1+1*IF(СКЗИ="да",1,0)+(2)*IF(КИИ="да",1,0)+1*IF(КТ="да",1,0)) ) +0.3*(SUM(F4,F6,F28,F37,F38,F39)/6) +0.2*(SUM(F40:F45,F29:F36,F7:F15,F17,F5, F16*IF(БР="да",1,0)) / (25+1*IF(БР="да",1,0))) -> 0 | G3: =0.3*( SUM(G23+G24+G25+G26+G27*IF(СКЗИ="да",1,0)) / (1+1+1+1+1*IF(СКЗИ="да",1,0)) ) +0.2*(SUM(G18+G19*IF(СКЗИ="да",1,0)+(G20+G21)*IF(КИИ="да",1,0)+G22*IF(КТ="да",1,0)) / (1+1*IF(СКЗИ="да",1,0)+(2)*IF(КИИ="да",1,0)+1*IF(КТ="да",1,0)) ) +0.3*(SUM(G4,G6,G28,G37,G38,G39)/6) +0.2*(SUM(G40:G45,G29:G36,G7:G15,G17,G5, G16*IF(БР="да",1,0)) / (25+1*IF(БР="да",1,0))) -> 0 | H3: =0.3*( SUM(H23+H24+H25+H26+H27*IF(СКЗИ="да",1,0)) / (1+1+1+1+1*IF(СКЗИ="да",1,0)) ) +0.2*(SUM(H18+H19*IF(СКЗИ="да",1,0)+(H20+H21)*IF(КИИ="да",1,0)+H22*IF(КТ="да",1,0)) / (1+1*IF(СКЗИ="да",1,0)+(2)*IF(КИИ="да",1,0)+1*IF(КТ="да",1,0)) ) +0.3*(SUM(H4,H6,H28,H37,H38,H39)/6) +0.2*(SUM(H40:H45,H29:H36,H7:H15,H17,H5, H16*IF(БР="да",1,0)) / (25+1*IF(БР="да",1,0))) -> 0 | I3: =0.3*( SUM(I23+I24+I25+I26+I27*IF(СКЗИ="да",1,0)) / (1+1+1+1+1*IF(СКЗИ="да",1,0)) ) +0.2*(SUM(I18+I19*IF(СКЗИ="да",1,0)+(I20+I21)*IF(КИИ="да",1,0)+I22*IF(КТ="да",1,0)) / (1+1*IF(СКЗИ="да",1,0)+(2)*IF(КИИ="да",1,0)+1*IF(КТ="да",1,0)) ) +0.3*(SUM(I4,I6,I28,I37,I38,I39)/6) +0.2*(SUM(I40:I45,I29:I36,I7:I15,I17,I5, I16*IF(БР="да",1,0)) / (25+1*IF(БР="да",1,0))) -> 0 | J3: =0.3*( SUM(J23+J24+J25+J26+J27*IF(СКЗИ="да",1,0)) / (1+1+1+1+1*IF(СКЗИ="да",1,0)) ) +0.2*(SUM(J18+J19*IF(СКЗИ="да",1,0)+(J20+J21)*IF(КИИ="да",1,0)+J22*IF(КТ="да",1,0)) / (1+1*IF(СКЗИ="да",1,0)+(2)*IF(КИИ="да",1,0)+1*IF(КТ="да",1,0)) ) +0.3*(SUM(J4,J6,J28,J37,J38,J39)/6) +0.2*(SUM(J40:J45,J29:J36,J7:J15,J17,J5, J16*IF(БР="да",1,0)) / (25+1*IF(БР="да",1,0))) -> 0 | ... M3: =0.3*( SUM(M23+M24+M25+M26+M27*IF(СКЗИ="да",1,0)) / (1+1+1+1+1*IF(СКЗИ="да",1,0)) ) +0.2*(SUM(M18+M19*IF(СКЗИ="да",1,0)+(M20+M21)*IF(КИИ="да",1,0)+M22*IF(КТ="да",1,0)) / (1+1*IF(СКЗИ="да",1,0)+(2)*IF(КИИ="да",1,0)+1*IF(КТ="да",1,0)) ) +0.3*(SUM(M4,M6,M28,M37,M38,M39)/6) +0.2*(SUM(M40:M45,M29:M36,M7:M15,M17,M5, M16*IF(БР="да",1,0)) / (25+1*IF(БР="да",1,0))) -> 0.35251776 | O3: прирост (дек.24- т.вр) | P3: =1-(0.3*( SUM(P23+P24+P25+P26+P27*IF(СКЗИ="да",1,0)) / (1+1+1+1+1*IF(СКЗИ="да",1,0)) ) +0.2*(SUM(P18+P19*IF(СКЗИ="да",1,0)+(P20+P21)*IF(КИИ="да",1,0)+P22*IF(КТ="да",1,0)) / (1+1*IF(СКЗИ="да",1,0)+(2)*IF(КИИ="да",1,0)+1*IF(КТ="да",1,0)) ) +0.3*(SUM(P4,P6,P28,P37,P38,P39)/6) +0.2*(SUM(P40:P45,P29:P36,P7:P15,P17,P5, P16*IF(БР="да",1,0)) / (25+1*IF(БР="да",1,0)))) -> 0.28188536 | R3: =1-(0.3*( SUM(R23+R24+R25+R26+R27*IF(СКЗИ="да",1,0)) / (1+1+1+1+1*IF(СКЗИ="да",1,0)) ) +0.2*(SUM(R18+R19*IF(СКЗИ="да",1,0)+(R20+R21)*IF(КИИ="да",1,0)+R22*IF(КТ="да",1,0)) / (1+1*IF(СКЗИ="да",1,0)+(2)*IF(КИИ="да",1,0)+1*IF(КТ="да",1,0)) ) +0.3*(SUM(R4,R6,R28,R37,R38,R39)/6) +0.2*(SUM(R40:R45,R29:R36,R7:R15,R17,R5, R16*IF(БР="да",1,0)) / (25+1*IF(БР="да",1,0)))) -> 0.071458828 | S3: =1-(0.3*( SUM(S23+S24+S25+S26+S27*IF(СКЗИ="да",1,0)) / (1+1+1+1+1*IF(СКЗИ="да",1,0)) ) +0.2*(SUM(S18+S19*IF(СКЗИ="да",1,0)+(S20+S21)*IF(КИИ="да",1,0)+S22*IF(КТ="да",1,0)) / (1+1*IF(СКЗИ="да",1,0)+(2)*IF(КИИ="да",1,0)+1*IF(КТ="да",1,0)) ) +0.3*(SUM(S4,S6,S28,S37,S38,S39)/6) +0.2*(SUM(S40:S45,S29:S36,S7:S15,S17,S5, S16*IF(БР="да",1,0)) / (25+1*IF(БР="да",1,0)))) -> 0.093196018 | T3: =1-(0.3*( SUM(T23+T24+T25+T26+T27*IF(СКЗИ="да",1,0)) / (1+1+1+1+1*IF(СКЗИ="да",1,0)) ) +0.2*(SUM(T18+T19*IF(СКЗИ="да",1,0)+(T20+T21)*IF(КИИ="да",1,0)+T22*IF(КТ="да",1,0)) / (1+1*IF(СКЗИ="да",1,0)+(2)*IF(КИИ="да",1,0)+1*IF(КТ="да",1,0)) ) +0.3*(SUM(T4,T6,T28,T37,T38,T39)/6) +0.2*(SUM(T40:T45,T29:T36,T7:T15,T17,T5, T16*IF(БР="да",1,0)) / (25+1*IF(БР="да",1,0)))) -> 0.28957767
A4: СУИБ | B4: ='Управление ИБ'!B42 -> Система управления ИБ | C4: ='Управление ИБ'!D42 -> 5 | D4: ='Управление ИБ'!E42 -> 4.64 | E4: ='Управление ИБ'!F42 -> 2 | F4: 0 | G4: 0 | H4: 0 | I4: 0 | J4: 0 | K4: ='Управление ИБ'!J42 -> #DIV/0! | L4: ='Управление ИБ'!K42 -> 2 | M4: ='Управление ИБ'!L42 -> 3.32 | N4: =L4-M4 -> -1.32 | O4: =I4-M4 -> -3.32 | P4: =IF((M4-L4)>=0,0,(M4-L4)*(-1)/L4) -> 0 | R4: =IF(($M4-C4)>=0,0,($M4-C4)*(-1)/C4) -> 0.336 | S4: =IF(($M4-D4)>=0,0,($M4-D4)*(-1)/D4) -> 0.28448276 | T4: =IF(($M4-E4)>=0,0,($M4-E4)*(-1)/E4) -> 0
B5: ='Управление ИБ'!B43 -> Управление рисками | C5: ='Управление ИБ'!D43 -> 4.8 | D5: ='Управление ИБ'!E43 -> 2 | E5: ='Управление ИБ'!F43 -> 1 | F5: 0 | G5: 0 | H5: 0 | I5: 0 | J5: 0 | K5: ='Управление ИБ'!J43 -> #DIV/0! | L5: ='Управление ИБ'!K43 -> 1 | M5: ='Управление ИБ'!L43 -> 0 | N5: =L5-M5 -> 1 | O5: =I5-M5 -> 0 | P5: =IF((M5-L5)>=0,0,(M5-L5)*(-1)/L5) -> 1 | R5: =IF(($M5-C5)>=0,0,($M5-C5)*(-1)/C5) -> 1 | S5: =IF(($M5-D5)>=0,0,($M5-D5)*(-1)/D5) -> 1 | T5: =IF(($M5-E5)>=0,0,($M5-E5)*(-1)/E5) -> 1
B6: ='Управление ИБ'!B44 -> Управление рисками в цепочке поставок | C6: ='Управление ИБ'!D44 -> 5 | D6: ='Управление ИБ'!E44 -> 3.2 | E6: ='Управление ИБ'!F44 -> 1.6 | F6: 0 | G6: 0 | H6: 0 | I6: 0 | J6: 0 | K6: ='Управление ИБ'!J44 -> #DIV/0! | L6: ='Управление ИБ'!K44 -> 1.6 | M6: ='Управление ИБ'!L44 -> 0 | N6: =L6-M6 -> 1.6 | O6: =I6-M6 -> 0 | P6: =IF((M6-L6)>=0,0,(M6-L6)*(-1)/L6) -> 1 | R6: =IF(($M6-C6)>=0,0,($M6-C6)*(-1)/C6) -> 1 | S6: =IF(($M6-D6)>=0,0,($M6-D6)*(-1)/D6) -> 1 | T6: =IF(($M6-E6)>=0,0,($M6-E6)*(-1)/E6) -> 1
B7: ='Управление ИБ'!B45 -> Инвентаризация | C7: ='Управление ИБ'!D45 -> 5 | D7: ='Управление ИБ'!E45 -> 3.2 | E7: ='Управление ИБ'!F45 -> 1.2307692 | F7: 0 | G7: 0 | H7: 0 | I7: 0 | J7: 0 | K7: ='Управление ИБ'!J45 -> #DIV/0! | L7: ='Управление ИБ'!K45 -> 1.2307692 | M7: ='Управление ИБ'!L45 -> 0.24615385 | N7: =L7-M7 -> 0.98461538 | O7: =I7-M7 -> -0.24615385 | P7: =IF((M7-L7)>=0,0,(M7-L7)*(-1)/L7) -> 0.8 | R7: =IF(($M7-C7)>=0,0,($M7-C7)*(-1)/C7) -> 0.95076923 | S7: =IF(($M7-D7)>=0,0,($M7-D7)*(-1)/D7) -> 0.92307692 | T7: =IF(($M7-E7)>=0,0,($M7-E7)*(-1)/E7) -> 0.8
B8: ='Управление ИБ'!B46 -> Управление активами | C8: ='Управление ИБ'!D46 -> 4.6 | D8: ='Управление ИБ'!E46 -> 3.12 | E8: ='Управление ИБ'!F46 -> 0.52 | F8: 0 | G8: 0 | H8: 0 | I8: 0 | J8: 0 | K8: ='Управление ИБ'!J46 -> #DIV/0! | L8: ='Управление ИБ'!K46 -> 0.52 | M8: ='Управление ИБ'!L46 -> 0.84 | N8: =L8-M8 -> -0.32 | O8: =I8-M8 -> -0.84 | P8: =IF((M8-L8)>=0,0,(M8-L8)*(-1)/L8) -> 0 | R8: =IF(($M8-C8)>=0,0,($M8-C8)*(-1)/C8) -> 0.8173913 | S8: =IF(($M8-D8)>=0,0,($M8-D8)*(-1)/D8) -> 0.73076923 | T8: =IF(($M8-E8)>=0,0,($M8-E8)*(-1)/E8) -> 0
B9: ='Управление ИБ'!B47 -> Управление доступом | C9: ='Управление ИБ'!D47 -> 4.46 | D9: ='Управление ИБ'!E47 -> 3.26 | E9: ='Управление ИБ'!F47 -> 2.14 | F9: 0 | G9: 0 | H9: 0 | I9: 0 | J9: 0 | K9: ='Управление ИБ'!J47 -> #DIV/0! | L9: ='Управление ИБ'!K47 -> 2.14 | M9: ='Управление ИБ'!L47 -> 1.32 | N9: =L9-M9 -> 0.82 | O9: =I9-M9 -> -1.32 | P9: =IF((M9-L9)>=0,0,(M9-L9)*(-1)/L9) -> 0.38317757 | R9: =IF(($M9-C9)>=0,0,($M9-C9)*(-1)/C9) -> 0.70403587 | S9: =IF(($M9-D9)>=0,0,($M9-D9)*(-1)/D9) -> 0.59509202 | T9: =IF(($M9-E9)>=0,0,($M9-E9)*(-1)/E9) -> 0.38317757
B10: ='Управление ИБ'!B48 -> Идентификация и аутентификация | C10: ='Управление ИБ'!D48 -> 5 | D10: ='Управление ИБ'!E48 -> 4.6 | E10: ='Управление ИБ'!F48 -> 3.3111111 | F10: 0 | G10: 0 | H10: 0 | I10: 0 | J10: 0 | K10: ='Управление ИБ'!J48 -> #DIV/0! | L10: ='Управление ИБ'!K48 -> 3.3111111 | M10: ='Управление ИБ'!L48 -> 0 | N10: =L10-M10 -> 3.3111111 | O10: =I10-M10 -> 0 | P10: =IF((M10-L10)>=0,0,(M10-L10)*(-1)/L10) -> 1 | R10: =IF(($M10-C10)>=0,0,($M10-C10)*(-1)/C10) -> 1 | S10: =IF(($M10-D10)>=0,0,($M10-D10)*(-1)/D10) -> 1 | T10: =IF(($M10-E10)>=0,0,($M10-E10)*(-1)/E10) -> 1
B11: ='Управление ИБ'!B49 -> Защита данных и информации | C11: ='Управление ИБ'!D49 -> 4.55 | D11: ='Управление ИБ'!E49 -> 3.7 | E11: ='Управление ИБ'!F49 -> 0.8 | F11: 0 | G11: 0 | H11: 0 | I11: 0 | J11: 0 | K11: ='Управление ИБ'!J49 -> #DIV/0! | L11: ='Управление ИБ'!K49 -> 0.8 | M11: ='Управление ИБ'!L49 -> 2.5 | N11: =L11-M11 -> -1.7 | O11: =I11-M11 -> -2.5 | P11: =IF((M11-L11)>=0,0,(M11-L11)*(-1)/L11) -> 0 | R11: =IF(($M11-C11)>=0,0,($M11-C11)*(-1)/C11) -> 0.45054945 | S11: =IF(($M11-D11)>=0,0,($M11-D11)*(-1)/D11) -> 0.32432432 | T11: =IF(($M11-E11)>=0,0,($M11-E11)*(-1)/E11) -> 0
B12: ='Управление ИБ'!B50 -> Обеспечение доступности | C12: ='Управление ИБ'!D50 -> 5 | D12: ='Управление ИБ'!E50 -> 3.92 | E12: ='Управление ИБ'!F50 -> 0 | F12: 0 | G12: 0 | H12: 0 | I12: 0 | J12: 0 | K12: ='Управление ИБ'!J50 -> #DIV/0! | L12: ='Управление ИБ'!K50 -> 0 | M12: ='Управление ИБ'!L50 -> 0 | N12: =L12-M12 -> 0 | O12: =I12-M12 -> 0 | P12: =IF((M12-L12)>=0,0,(M12-L12)*(-1)/L12) -> 0 | R12: =IF(($M12-C12)>=0,0,($M12-C12)*(-1)/C12) -> 1 | S12: =IF(($M12-D12)>=0,0,($M12-D12)*(-1)/D12) -> 1 | T12: =IF(($M12-E12)>=0,0,($M12-E12)*(-1)/E12) -> 0
B13: ='Управление ИБ'!B51 -> Персонал | C13: ='Управление ИБ'!D51 -> 5 | D13: ='Управление ИБ'!E51 -> 5 | E13: ='Управление ИБ'!F51 -> 5 | F13: 0 | G13: 0 | H13: 0 | I13: 0 | J13: 0 | K13: ='Управление ИБ'!J51 -> #DIV/0! | L13: ='Управление ИБ'!K51 -> 5 | M13: ='Управление ИБ'!L51 -> 0 | N13: =L13-M13 -> 5 | O13: =I13-M13 -> 0 | P13: =IF((M13-L13)>=0,0,(M13-L13)*(-1)/L13) -> 1 | R13: =IF(($M13-C13)>=0,0,($M13-C13)*(-1)/C13) -> 1 | S13: =IF(($M13-D13)>=0,0,($M13-D13)*(-1)/D13) -> 1 | T13: =IF(($M13-E13)>=0,0,($M13-E13)*(-1)/E13) -> 1
B14: ='Управление ИБ'!B52 -> Осведомленность пользователей и обучение персонала | C14: ='Управление ИБ'!D52 -> 5 | D14: ='Управление ИБ'!E52 -> 3.2 | E14: ='Управление ИБ'!F52 -> 1.6 | F14: 0 | G14: 0 | H14: 0 | I14: 0 | J14: 0 | K14: ='Управление ИБ'!J52 -> #DIV/0! | L14: ='Управление ИБ'!K52 -> 1.6 | M14: ='Управление ИБ'!L52 -> 0.14545455 | N14: =L14-M14 -> 1.4545455 | O14: =I14-M14 -> -0.14545455 | P14: =IF((M14-L14)>=0,0,(M14-L14)*(-1)/L14) -> 0.90909091 | R14: =IF(($M14-C14)>=0,0,($M14-C14)*(-1)/C14) -> 0.97090909 | S14: =IF(($M14-D14)>=0,0,($M14-D14)*(-1)/D14) -> 0.95454545 | T14: =IF(($M14-E14)>=0,0,($M14-E14)*(-1)/E14) -> 0.90909091
B15: ='Управление ИБ'!B53 -> Процессы | C15: ='Управление ИБ'!D53 -> 4.0869565 | D15: ='Управление ИБ'!E53 -> 2.8 | E15: ='Управление ИБ'!F53 -> 0.67826087 | F15: 0 | G15: 0 | H15: 0 | I15: 0 | J15: 0 | K15: ='Управление ИБ'!J53 -> 0 | L15: ='Управление ИБ'!K53 -> 0.67826087 | M15: ='Управление ИБ'!L53 -> 0.24347826 | N15: =L15-M15 -> 0.43478261 | O15: =I15-M15 -> -0.24347826 | P15: =IF((M15-L15)>=0,0,(M15-L15)*(-1)/L15) -> 0.64102564 | R15: =IF(($M15-C15)>=0,0,($M15-C15)*(-1)/C15) -> 0.94042553 | S15: =IF(($M15-D15)>=0,0,($M15-D15)*(-1)/D15) -> 0.91304348 | T15: =IF(($M15-E15)>=0,0,($M15-E15)*(-1)/E15) -> 0.64102564
B16: ='Управление ИБ'!B54 -> Безопасная разработка | C16: ='Управление ИБ'!D54 -> 4.9285714 | D16: ='Управление ИБ'!E54 -> 3.8285714 | E16: ='Управление ИБ'!F54 -> 0.98571429 | F16: 0 | G16: 0 | H16: 0 | I16: 0 | J16: 0 | K16: ='Управление ИБ'!J54 -> #DIV/0! | L16: ='Управление ИБ'!K54 -> 0.98571429 | M16: ='Управление ИБ'!L54 -> 0 | N16: =L16-M16 -> 0.98571429 | O16: =I16-M16 -> 0 | P16: =IF((M16-L16)>=0,0,(M16-L16)*(-1)/L16) -> 1 | R16: =IF(($M16-C16)>=0,0,($M16-C16)*(-1)/C16) -> 1 | S16: =IF(($M16-D16)>=0,0,($M16-D16)*(-1)/D16) -> 1 | T16: =IF(($M16-E16)>=0,0,($M16-E16)*(-1)/E16) -> 1
B17: ='Управление ИБ'!B55 -> Физический доступ | C17: ='Управление ИБ'!D55 -> 5 | D17: ='Управление ИБ'!E55 -> 4.64 | E17: ='Управление ИБ'!F55 -> 4.32 | F17: 0 | G17: 0 | H17: 0 | I17: 0 | J17: 0 | K17: ='Управление ИБ'!J55 -> #DIV/0! | L17: ='Управление ИБ'!K55 -> 4.32 | M17: ='Управление ИБ'!L55 -> 0 | N17: =L17-M17 -> 4.32 | O17: =I17-M17 -> 0 | P17: =IF((M17-L17)>=0,0,(M17-L17)*(-1)/L17) -> 1 | R17: =IF(($M17-C17)>=0,0,($M17-C17)*(-1)/C17) -> 1 | S17: =IF(($M17-D17)>=0,0,($M17-D17)*(-1)/D17) -> 1 | T17: =IF(($M17-E17)>=0,0,($M17-E17)*(-1)/E17) -> 1
A18: ='Нормативное соответствие'!B1 -> Нормативное соответствие | B18: ='Нормативное соответствие'!B42 -> Персональные данные | C18: ='Нормативное соответствие'!D42 -> 5 | D18: ='Нормативное соответствие'!E42 -> 5 | E18: ='Нормативное соответствие'!F42 -> 5 | F18: 0 | G18: 0 | H18: 0 | I18: 0 | J18: 0 | K18: ='Нормативное соответствие'!J42 -> #DIV/0! | L18: ='Нормативное соответствие'!K42 -> 5 | M18: ='Нормативное соответствие'!L42 -> 0.20833333 | N18: =L18-M18 -> 4.7916667 | O18: =I18-M18 -> -0.20833333 | P18: =IF((M18-L18)>=0,0,(M18-L18)*(-1)/L18) -> 0.95833333 | R18: =IF(($M18-C18)>=0,0,($M18-C18)*(-1)/C18) -> 0.95833333 | S18: =IF(($M18-D18)>=0,0,($M18-D18)*(-1)/D18) -> 0.95833333 | T18: =IF(($M18-E18)>=0,0,($M18-E18)*(-1)/E18) -> 0.95833333
B19: ='Нормативное соответствие'!B45 -> Средства криптографической защиты информации (СКЗИ ГОСТ) | C19: ='Нормативное соответствие'!D45 -> 5 | D19: ='Нормативное соответствие'!E45 -> 4.82 | E19: ='Нормативное соответствие'!F45 -> 4.66 | F19: 0 | G19: 0 | H19: 0 | I19: 0 | J19: 0 | K19: ='Нормативное соответствие'!J45 -> #DIV/0! | L19: ='Нормативное соответствие'!K45 -> 4.66 | M19: ='Нормативное соответствие'!L45 -> 0 | N19: =L19-M19 -> 4.66 | O19: =I19-M19 -> 0 | P19: =IF((M19-L19)>=0,0,(M19-L19)*(-1)/L19) -> 1 | R19: =IF(($M19-C19)>=0,0,($M19-C19)*(-1)/C19) -> 1 | S19: =IF(($M19-D19)>=0,0,($M19-D19)*(-1)/D19) -> 1 | T19: =IF(($M19-E19)>=0,0,($M19-E19)*(-1)/E19) -> 1
B20: ='Нормативное соответствие'!B43 -> КИИ | C20: ='Нормативное соответствие'!D43 -> 0 | D20: ='Нормативное соответствие'!E43 -> 0 | E20: ='Нормативное соответствие'!F43 -> 0 | F20: 0 | G20: 0 | H20: 0 | I20: 0 | J20: 0 | K20: ='Нормативное соответствие'!J43 -> #DIV/0! | L20: ='Нормативное соответствие'!K43 -> 0 | M20: ='Нормативное соответствие'!L43 -> 0 | N20: =L20-M20 -> 0 | O20: =I20-M20 -> 0 | P20: =IF((M20-L20)>=0,0,(M20-L20)*(-1)/L20) -> 0 | R20: =IF(($M20-C20)>=0,0,($M20-C20)*(-1)/C20) -> 0 | S20: =IF(($M20-D20)>=0,0,($M20-D20)*(-1)/D20) -> 0 | T20: =IF(($M20-E20)>=0,0,($M20-E20)*(-1)/E20) -> 0
B21: ='Нормативное соответствие'!B46 -> 250 указ | C21: ='Нормативное соответствие'!D46 -> 0 | D21: ='Нормативное соответствие'!E46 -> 0 | E21: ='Нормативное соответствие'!F46 -> 0 | F21: 0 | G21: 0 | H21: 0 | I21: 0 | J21: 0 | K21: ='Нормативное соответствие'!J46 -> #DIV/0! | L21: ='Нормативное соответствие'!K46 -> 0.43402778 | M21: ='Нормативное соответствие'!L46 -> 0.48611111 | N21: =L21-M21 -> -0.052083333 | O21: =I21-M21 -> -0.48611111 | P21: =IF((M21-L21)>=0,0,(M21-L21)*(-1)/L21) -> 0 | R21: =IF(($M21-C21)>=0,0,($M21-C21)*(-1)/C21) -> 0 | S21: =IF(($M21-D21)>=0,0,($M21-D21)*(-1)/D21) -> 0 | T21: =IF(($M21-E21)>=0,0,($M21-E21)*(-1)/E21) -> 0
B22: ='Нормативное соответствие'!B44 -> Коммерческая тайна | C22: ='Нормативное соответствие'!D44 -> 5 | D22: ='Нормативное соответствие'!E44 -> 5 | E22: ='Нормативное соответствие'!F44 -> 5 | F22: 0 | G22: 0 | H22: 0 | I22: 0 | J22: 0 | K22: ='Нормативное соответствие'!J44 -> #DIV/0! | L22: ='Нормативное соответствие'!K44 -> 5 | M22: ='Нормативное соответствие'!L44 -> 1 | N22: =L22-M22 -> 4 | O22: =I22-M22 -> -1 | P22: =IF((M22-L22)>=0,0,(M22-L22)*(-1)/L22) -> 0.8 | R22: =IF(($M22-C22)>=0,0,($M22-C22)*(-1)/C22) -> 0.8 | S22: =IF(($M22-D22)>=0,0,($M22-D22)*(-1)/D22) -> 0.8 | T22: =IF(($M22-E22)>=0,0,($M22-E22)*(-1)/E22) -> 0.8
A23: СЗИ | B23: =СЗИ!B29 -> Защита от ВПО | C23: =СЗИ!D29 -> 4.59375 | D23: =СЗИ!E29 -> 4.1875 | E23: =СЗИ!F29 -> 3.49375 | F23: 0 | G23: 0 | H23: 0 | I23: 0 | J23: 0 | K23: =СЗИ!J29 -> #DIV/0! | L23: =СЗИ!K29 -> 3.49375 | M23: =СЗИ!L29 -> 0 | N23: =L23-M23 -> 3.49375 | O23: =I23-M23 -> 0 | P23: =IF((M23-L23)>=0,0,(M23-L23)*(-1)/L23) -> 1 | R23: =IF(($M23-C23)>=0,0,($M23-C23)*(-1)/C23) -> 1 | S23: =IF(($M23-D23)>=0,0,($M23-D23)*(-1)/D23) -> 1 | T23: =IF(($M23-E23)>=0,0,($M23-E23)*(-1)/E23) -> 1
B24: =СЗИ!B30 -> Двухфакторная аутентификация пользователей (2FA) | C24: =СЗИ!D30 -> 5 | D24: =СЗИ!E30 -> 5 | E24: =СЗИ!F30 -> 3.65 | F24: 0 | G24: 0 | H24: 0 | I24: 0 | J24: 0 | K24: =СЗИ!J30 -> #DIV/0! | L24: =СЗИ!K30 -> 3.65 | M24: =СЗИ!L30 -> 0 | N24: =L24-M24 -> 3.65 | O24: =I24-M24 -> 0 | P24: =IF((M24-L24)>=0,0,(M24-L24)*(-1)/L24) -> 1 | R24: =IF(($M24-C24)>=0,0,($M24-C24)*(-1)/C24) -> 1 | S24: =IF(($M24-D24)>=0,0,($M24-D24)*(-1)/D24) -> 1 | T24: =IF(($M24-E24)>=0,0,($M24-E24)*(-1)/E24) -> 1
B25: =СЗИ!B31 -> Защита внешнего инфраструктурного периметра (CPT) | C25: =СЗИ!D31 -> 4.5833333 | D25: =СЗИ!E31 -> 4.1666667 | E25: =СЗИ!F31 -> 3.25 | F25: 0 | G25: 0 | H25: 0 | I25: 0 | J25: 0 | K25: =СЗИ!J31 -> #DIV/0! | L25: =СЗИ!K31 -> 3.25 | M25: =СЗИ!L31 -> 0 | N25: =L25-M25 -> 3.25 | O25: =I25-M25 -> 0 | P25: =IF((M25-L25)>=0,0,(M25-L25)*(-1)/L25) -> 1 | R25: =IF(($M25-C25)>=0,0,($M25-C25)*(-1)/C25) -> 1 | S25: =IF(($M25-D25)>=0,0,($M25-D25)*(-1)/D25) -> 1 | T25: =IF(($M25-E25)>=0,0,($M25-E25)*(-1)/E25) -> 1
B26: =СЗИ!B32 -> Защита удаленного доступа (RA VPN) | C26: =СЗИ!D32 -> 5 | D26: =СЗИ!E32 -> 4.55 | E26: =СЗИ!F32 -> 4.1 | F26: 0 | G26: 0 | H26: 0 | I26: 0 | J26: 0 | K26: =СЗИ!J32 -> #DIV/0! | L26: =СЗИ!K32 -> 4.1 | M26: =СЗИ!L32 -> 0 | N26: =L26-M26 -> 4.1 | O26: =I26-M26 -> 0 | P26: =IF((M26-L26)>=0,0,(M26-L26)*(-1)/L26) -> 1 | R26: =IF(($M26-C26)>=0,0,($M26-C26)*(-1)/C26) -> 1 | S26: =IF(($M26-D26)>=0,0,($M26-D26)*(-1)/D26) -> 1 | T26: =IF(($M26-E26)>=0,0,($M26-E26)*(-1)/E26) -> 1
B27: =СЗИ!B33 -> Средства криптографической защиты информации (СКЗИ ГОСТ) | C27: =СЗИ!D33 -> 5 | D27: =СЗИ!E33 -> 4.955 | E27: =СЗИ!F33 -> 4.465 | F27: 0 | G27: 0 | H27: 0 | I27: 0 | J27: 0 | K27: =СЗИ!J33 -> #DIV/0! | L27: =СЗИ!K33 -> 4.465 | M27: =СЗИ!L33 -> 0.91111111 | N27: =L27-M27 -> 3.5538889 | O27: =I27-M27 -> -0.91111111 | P27: =IF((M27-L27)>=0,0,(M27-L27)*(-1)/L27) -> 0.79594376 | R27: =IF(($M27-C27)>=0,0,($M27-C27)*(-1)/C27) -> 0.81777778 | S27: =IF(($M27-D27)>=0,0,($M27-D27)*(-1)/D27) -> 0.81612288 | T27: =IF(($M27-E27)>=0,0,($M27-E27)*(-1)/E27) -> 0.79594376
B28: =СЗИ!B34 -> Мониторинг, обнаружение, анализ и реагирование на инциденты в информационных системах (SOC) | C28: =СЗИ!D34 -> 4.6346154 | D28: =СЗИ!E34 -> 3.7205128 | E28: =СЗИ!F34 -> 0.041025641 | F28: 0 | G28: 0 | H28: 0 | I28: 0 | J28: 0 | K28: =СЗИ!J34 -> #DIV/0! | L28: =СЗИ!K34 -> 0.041025641 | M28: =СЗИ!L34 -> 0 | N28: =L28-M28 -> 0.041025641 | O28: =I28-M28 -> 0 | P28: =IF((M28-L28)>=0,0,(M28-L28)*(-1)/L28) -> 1 | R28: =IF(($M28-C28)>=0,0,($M28-C28)*(-1)/C28) -> 1 | S28: =IF(($M28-D28)>=0,0,($M28-D28)*(-1)/D28) -> 1 | T28: =IF(($M28-E28)>=0,0,($M28-E28)*(-1)/E28) -> 1
B29: =СЗИ!B35 -> Сетевая безопасность (МСЭ\NGFW) | C29: =СЗИ!D35 -> 5 | D29: =СЗИ!E35 -> 4.1 | E29: =СЗИ!F35 -> 0 | F29: 0 | G29: 0 | H29: 0 | I29: 0 | J29: 0 | K29: =СЗИ!J35 -> #DIV/0! | L29: =СЗИ!K35 -> 0 | M29: =СЗИ!L35 -> 0 | N29: =L29-M29 -> 0 | O29: =I29-M29 -> 0 | P29: =IF((M29-L29)>=0,0,(M29-L29)*(-1)/L29) -> 0 | R29: =IF(($M29-C29)>=0,0,($M29-C29)*(-1)/C29) -> 1 | S29: =IF(($M29-D29)>=0,0,($M29-D29)*(-1)/D29) -> 1 | T29: =IF(($M29-E29)>=0,0,($M29-E29)*(-1)/E29) -> 0
B30: =СЗИ!B36 -> Защита и фильтрация сетевого трафика (Прокси-сервер) | C30: =СЗИ!D36 -> 5 | D30: =СЗИ!E36 -> 3.025 | E30: =СЗИ!F36 -> 0 | F30: 0 | G30: 0 | H30: 0 | I30: 0 | J30: 0 | K30: =СЗИ!J36 -> #DIV/0! | L30: =СЗИ!K36 -> 0 | M30: =СЗИ!L36 -> 0 | N30: =L30-M30 -> 0 | O30: =I30-M30 -> 0 | P30: =IF((M30-L30)>=0,0,(M30-L30)*(-1)/L30) -> 0 | R30: =IF(($M30-C30)>=0,0,($M30-C30)*(-1)/C30) -> 1 | S30: =IF(($M30-D30)>=0,0,($M30-D30)*(-1)/D30) -> 1 | T30: =IF(($M30-E30)>=0,0,($M30-E30)*(-1)/E30) -> 0
B31: =СЗИ!B37 -> Сканер уязвимостей | C31: =СЗИ!D37 -> 4.6666667 | D31: =СЗИ!E37 -> 3.7333333 | E31: =СЗИ!F37 -> 0 | F31: 0 | G31: 0 | H31: 0 | I31: 0 | J31: 0 | K31: =СЗИ!J37 -> #DIV/0! | L31: =СЗИ!K37 -> 0 | M31: =СЗИ!L37 -> 0.33333333 | N31: =L31-M31 -> -0.33333333 | O31: =I31-M31 -> -0.33333333 | P31: =IF((M31-L31)>=0,0,(M31-L31)*(-1)/L31) -> 0 | R31: =IF(($M31-C31)>=0,0,($M31-C31)*(-1)/C31) -> 0.92857143 | S31: =IF(($M31-D31)>=0,0,($M31-D31)*(-1)/D31) -> 0.91071429 | T31: =IF(($M31-E31)>=0,0,($M31-E31)*(-1)/E31) -> 0
B32: =СЗИ!B38 -> Защита от вредоносного трафика (Anti-DDoS) | C32: =СЗИ!D38 -> 5 | D32: =СЗИ!E38 -> 4.2 | E32: =СЗИ!F38 -> 0 | F32: 0 | G32: 0 | H32: 0 | I32: 0 | J32: 0 | K32: =СЗИ!J38 -> #DIV/0! | L32: =СЗИ!K38 -> 0 | M32: =СЗИ!L38 -> 0 | N32: =L32-M32 -> 0 | O32: =I32-M32 -> 0 | P32: =IF((M32-L32)>=0,0,(M32-L32)*(-1)/L32) -> 0 | R32: =IF(($M32-C32)>=0,0,($M32-C32)*(-1)/C32) -> 1 | S32: =IF(($M32-D32)>=0,0,($M32-D32)*(-1)/D32) -> 1 | T32: =IF(($M32-E32)>=0,0,($M32-E32)*(-1)/E32) -> 0
B33: =СЗИ!B39 -> Фильтрация нежелательных и вредоносных сообщений (Антиспам) | C33: =СЗИ!D39 -> 5 | D33: =СЗИ!E39 -> 1 | E33: =СЗИ!F39 -> 0 | F33: 0 | G33: 0 | H33: 0 | I33: 0 | J33: 0 | K33: =СЗИ!J39 -> #DIV/0! | L33: =СЗИ!K39 -> 0 | M33: =СЗИ!L39 -> 0 | N33: =L33-M33 -> 0 | O33: =I33-M33 -> 0 | P33: =IF((M33-L33)>=0,0,(M33-L33)*(-1)/L33) -> 0 | R33: =IF(($M33-C33)>=0,0,($M33-C33)*(-1)/C33) -> 1 | S33: =IF(($M33-D33)>=0,0,($M33-D33)*(-1)/D33) -> 1 | T33: =IF(($M33-E33)>=0,0,($M33-E33)*(-1)/E33) -> 0
B34: =СЗИ!B40 -> Обнаружение и блокирование сетевых атак на web-приложении (WAF) | C34: =СЗИ!D40 -> 4.8 | D34: =СЗИ!E40 -> 1.24 | E34: =СЗИ!F40 -> 0.84 | F34: 0 | G34: 0 | H34: 0 | I34: 0 | J34: 0 | K34: =СЗИ!J40 -> #DIV/0! | L34: =СЗИ!K40 -> 0.84 | M34: =СЗИ!L40 -> 0 | N34: =L34-M34 -> 0.84 | O34: =I34-M34 -> 0 | P34: =IF((M34-L34)>=0,0,(M34-L34)*(-1)/L34) -> 1 | R34: =IF(($M34-C34)>=0,0,($M34-C34)*(-1)/C34) -> 1 | S34: =IF(($M34-D34)>=0,0,($M34-D34)*(-1)/D34) -> 1 | T34: =IF(($M34-E34)>=0,0,($M34-E34)*(-1)/E34) -> 1
B35: =СЗИ!B41 -> Контроль учетных записей (PAM) | C35: =СЗИ!D41 -> 5 | D35: =СЗИ!E41 -> 0 | E35: =СЗИ!F41 -> 0 | F35: 0 | G35: 0 | H35: 0 | I35: 0 | J35: 0 | K35: =СЗИ!J41 -> 0 | L35: =СЗИ!K41 -> 0 | M35: =СЗИ!L41 -> 0 | N35: =L35-M35 -> 0 | O35: =I35-M35 -> 0 | P35: =IF((M35-L35)>=0,0,(M35-L35)*(-1)/L35) -> 0 | R35: =IF(($M35-C35)>=0,0,($M35-C35)*(-1)/C35) -> 1 | S35: =IF(($M35-D35)>=0,0,($M35-D35)*(-1)/D35) -> 0 | T35: =IF(($M35-E35)>=0,0,($M35-E35)*(-1)/E35) -> 0
B36: =СЗИ!B42 -> Предотвращение утечки данных (Data Loss Prevention (DLP) | C36: =СЗИ!D42 -> 4.8214286 | D36: =СЗИ!E42 -> 0 | E36: =СЗИ!F42 -> 0 | F36: 0 | G36: 0 | H36: 0 | I36: 0 | J36: 0 | K36: =СЗИ!J42 -> 0 | L36: =СЗИ!K42 -> 0 | M36: =СЗИ!L42 -> 0 | N36: =L36-M36 -> 0 | O36: =I36-M36 -> 0 | P36: =IF((M36-L36)>=0,0,(M36-L36)*(-1)/L36) -> 0 | R36: =IF(($M36-C36)>=0,0,($M36-C36)*(-1)/C36) -> 1 | S36: =IF(($M36-D36)>=0,0,($M36-D36)*(-1)/D36) -> 0 | T36: =IF(($M36-E36)>=0,0,($M36-E36)*(-1)/E36) -> 0
A37: Мониторинг | B37: =Мониторинг!B39 -> SIEM (внедрение системы как СЗИ) | C37: =Мониторинг!D39 -> 4.9038462 | D37: =Мониторинг!E39 -> 3.5615385 | E37: =Мониторинг!F39 -> 0.12307692 | F37: 0 | G37: 0 | H37: 0 | I37: 0 | J37: 0 | K37: =Мониторинг!J39 -> #DIV/0! | L37: =Мониторинг!K39 -> 0.12307692 | M37: =Мониторинг!L39 -> 0 | N37: =L37-M37 -> 0.12307692 | O37: =I37-M37 -> 0 | P37: =IF((M37-L37)>=0,0,(M37-L37)*(-1)/L37) -> 1 | R37: =IF(($M37-C37)>=0,0,($M37-C37)*(-1)/C37) -> 1 | S37: =IF(($M37-D37)>=0,0,($M37-D37)*(-1)/D37) -> 1 | T37: =IF(($M37-E37)>=0,0,($M37-E37)*(-1)/E37) -> 1
B38: =Мониторинг!B38 -> Аномалии и события (Хранение информации о событиях) | C38: =Мониторинг!D38 -> 5 | D38: =Мониторинг!E38 -> 5 | E38: =Мониторинг!F38 -> 0 | F38: 0 | G38: 0 | H38: 0 | I38: 0 | J38: 0 | K38: =Мониторинг!J38 -> #DIV/0! | L38: =Мониторинг!K38 -> 0 | M38: =Мониторинг!L38 -> 0 | N38: =L38-M38 -> 0 | O38: =I38-M38 -> 0 | P38: =IF((M38-L38)>=0,0,(M38-L38)*(-1)/L38) -> 0 | R38: =IF(($M38-C38)>=0,0,($M38-C38)*(-1)/C38) -> 1 | S38: =IF(($M38-D38)>=0,0,($M38-D38)*(-1)/D38) -> 1 | T38: =IF(($M38-E38)>=0,0,($M38-E38)*(-1)/E38) -> 0
B39: =Мониторинг!B40 -> Мониторинг - Процессы | C39: =Мониторинг!D40 -> 4 | D39: =Мониторинг!E40 -> 2.6 | E39: =Мониторинг!F40 -> 0 | F39: 0 | G39: 0 | H39: 0 | I39: 0 | J39: 0 | K39: =Мониторинг!J40 -> #DIV/0! | L39: =Мониторинг!K40 -> 0 | M39: =Мониторинг!L40 -> 0 | N39: =L39-M39 -> 0 | O39: =I39-M39 -> 0 | P39: =IF((M39-L39)>=0,0,(M39-L39)*(-1)/L39) -> 0 | R39: =IF(($M39-C39)>=0,0,($M39-C39)*(-1)/C39) -> 1 | S39: =IF(($M39-D39)>=0,0,($M39-D39)*(-1)/D39) -> 1 | T39: =IF(($M39-E39)>=0,0,($M39-E39)*(-1)/E39) -> 0
A40: Реагирование | B40: =Реагирование!B30 -> Планирование реагирования | C40: =Реагирование!D30 -> 4.5 | D40: =Реагирование!E30 -> 3.1 | E40: =Реагирование!F30 -> 0.5 | F40: 0 | G40: 0 | H40: 0 | I40: 0 | J40: 0 | K40: =Реагирование!J30 -> #DIV/0! | L40: =Реагирование!K30 -> 0.5 | M40: =Реагирование!L30 -> 0 | N40: =L40-M40 -> 0.5 | O40: =I40-M40 -> 0 | P40: =IF((M40-L40)>=0,0,(M40-L40)*(-1)/L40) -> 1 | R40: =IF(($M40-C40)>=0,0,($M40-C40)*(-1)/C40) -> 1 | S40: =IF(($M40-D40)>=0,0,($M40-D40)*(-1)/D40) -> 1 | T40: =IF(($M40-E40)>=0,0,($M40-E40)*(-1)/E40) -> 1
...

Sheet Программа
K1: =SUBTOTAL(3,K3:K9672) -> 611 | M1: =SUBTOTAL(3,M3:M9672) -> 611 | N1: =SUBTOTAL(3,N3:N9672) -> 609 | O1: =SUBTOTAL(3,O3:O9672) -> 3 | P1: =SUBTOTAL(3,P3:P9672) -> 0
A2: Тематика | B2: Домен | C2: Наименование показателя | D2: Сокращенное наименование | E2: КБ3 | F2: КБ2 | G2: КБ1 | H2: Приоритет | I2: Расчетный показатель 2025 | J2: Начальный показатель (на 01.25) | K2: Текущий показатель | L2: Динамика | M2: Индикатор | N2: Пункт плана | O2: Артефакты достижения | P2: Методика проверки
A3: СЗИ | B3: Защита от ВПО | C3: =СЗИ!B46 -> Процент покрытия инфраструктуры лицензиями на антивирусное ПО | D3: =СЗИ!C46 -> СЗИ.ВПО.1 | E3: =СЗИ!D46 -> 5 | F3: =СЗИ!E46 -> 5 | G3: =СЗИ!F46 -> 5 | H3: =СЗИ!P46 -> 1.01 | I3: =СЗИ!K46 -> 5 | J3: =СЗИ!I46 -> 0 | K3: =СЗИ!L46 -> 0 | L3: =IF(J3=I3," ",K3-J3) -> 0 | M3: =IF(H3<100, IF(K3>=G3,0,I3-K3), IF(H3<300, IF(K3>=F3,0,I3-K3), IF(K3>=E3,0,I3-K3))) -> 5 | N3: =СЗИ!Q46 -> - Закупить средства АВЗ в объеме, достаточном для охвата инфраструктуры Общества
A4: СЗИ | B4: Защита от ВПО | C4: =СЗИ!B47 -> Процент покрытия инфраструктуры средствами антивирусного ПО | D4: =СЗИ!C47 -> СЗИ.ВПО.2 | E4: =СЗИ!D47 -> 4.75 | F4: =СЗИ!E47 -> 4.5 | G4: =СЗИ!F47 -> 3.75 | H4: =СЗИ!P47 -> 1.02 | I4: =СЗИ!K47 -> 3.75 | J4: =СЗИ!I47 -> 0 | K4: =СЗИ!L47 -> 0 | L4: =IF(J4=I4," ",K4-J4) -> 0 | M4: =IF(H4<100, IF(K4>=G4,0,I4-K4), IF(H4<300, IF(K4>=F4,0,I4-K4), IF(K4>=E4,0,I4-K4))) -> 3.75 | N4: =СЗИ!Q47 -> - Обеспечить установку средств АВЗ не менее чем на 75% хостов инфраструктуры Общества
A5: СЗИ | B5: Защита от ВПО | C5: =СЗИ!B48 -> Осуществляется централизованное управление средствами антивирусной защиты (САВЗ) | D5: =СЗИ!C48 -> СЗИ.ВПО.3 | E5: =СЗИ!D48 -> 5 | F5: =СЗИ!E48 -> 5 | G5: =СЗИ!F48 -> 3.2 | H5: =СЗИ!P48 -> 1.03 | I5: =СЗИ!K48 -> 3.2 | J5: =СЗИ!I48 -> 0 | K5: =СЗИ!L48 -> 0 | L5: =IF(J5=I5," ",K5-J5) -> 0 | M5: =IF(H5<100, IF(K5>=G5,0,I5-K5), IF(H5<300, IF(K5>=F5,0,I5-K5), IF(K5>=E5,0,I5-K5))) -> 3.2 | N5: =СЗИ!Q48 -> - Создать систему централизованного управления средствами АВЗ и обеспечить подключение к ней основных элементов инфраструктуры
A6: СЗИ | B6: Защита от ВПО | C6: =СЗИ!B49 -> Настроены и применены централизованные политики АВЗ, рекомендованые ПАО "Ростелеком" | D6: =СЗИ!C49 -> СЗИ.ВПО.4 | E6: =СЗИ!D49 -> 5 | F6: =СЗИ!E49 -> 5 | G6: =СЗИ!F49 -> 5 | H6: =СЗИ!P49 -> 1.04 | I6: =СЗИ!K49 -> 5 | J6: =СЗИ!I49 -> 0 | K6: =СЗИ!L49 -> 0 | L6: =IF(J6=I6," ",K6-J6) -> 0 | M6: =IF(H6<100, IF(K6>=G6,0,I6-K6), IF(H6<300, IF(K6>=F6,0,I6-K6), IF(K6>=E6,0,I6-K6))) -> 5 | N6: =СЗИ!Q49 -> - Получить в Блоке ИБ ПАО Ростелеком конфигурационные решения (КР) по настройке средств АВЗ _x000D_- Применить настройки средств АВЗ для рабочих станций _x000D_- Применить настройки средств АВЗ для серверов _x000D_- Применить настройки средств АВЗ для серверов СУБД _x000D_- Применить настройки средств АВЗ для платформ виртуализации _x000D_- Применить настройки средств АВЗ для прокси-серверов _x000D_- Применить настройки средств АВЗ для почтовых серверов
A7: СЗИ | B7: Защита от ВПО | C7: =СЗИ!B50 -> Архитектура решения соответствует ТТР Блока ИБ | D7: =СЗИ!C50 -> СЗИ.ВПО.5 | E7: =СЗИ!D50 -> 5 | F7: =СЗИ!E50 -> 5 | G7: =СЗИ!F50 -> 5 | H7: =СЗИ!P50 -> 1.05 | I7: =СЗИ!K50 -> 5 | J7: =СЗИ!I50 -> 0 | K7: =СЗИ!L50 -> 0 | L7: =IF(J7=I7," ",K7-J7) -> 0 | M7: =IF(H7<100, IF(K7>=G7,0,I7-K7), IF(H7<300, IF(K7>=F7,0,I7-K7), IF(K7>=E7,0,I7-K7))) -> 5 | N7: =СЗИ!Q50 -> - Получить в Блоке ИБ ПАО Ростелеком конфигурационные решения (КР) по архитектуре средств АВЗ _x000D_- Организовать средства централизованного управления АВЗ в соответствии с КР
A8: СЗИ | B8: Защита от ВПО | C8: =СЗИ!B51 -> Процесс контроля работоспособности САВЗ | D8: =СЗИ!C51 -> СЗИ.ВПО.6 | E8: =СЗИ!D51 -> 4 | F8: =СЗИ!E51 -> 3 | G8: =СЗИ!F51 -> 2 | H8: =СЗИ!P51 -> 1.06 | I8: =СЗИ!K51 -> 2 | J8: =СЗИ!I51 -> 0 | K8: =СЗИ!L51 -> 0 | L8: =IF(J8=I8," ",K8-J8) -> 0 | M8: =IF(H8<100, IF(K8>=G8,0,I8-K8), IF(H8<300, IF(K8>=F8,0,I8-K8), IF(K8>=E8,0,I8-K8))) -> 2 | N8: =СЗИ!Q51 -> - Разработать или Получить в Блоке ИБ ПАО Ростелеком типовое описание процесса контроля рабоспособности средств АВЗ _x000D_- Утвердить в Обществе ВНД, описывающий процесс контроля рабоспособности средств АВЗ
A9: СЗИ | B9: Защита от ВПО | C9: =СЗИ!B52 -> Процесс обновления антивирусных средств | D9: =СЗИ!C52 -> СЗИ.ВПО.7 | E9: =СЗИ!D52 -> 4 | F9: =СЗИ!E52 -> 3 | G9: =СЗИ!F52 -> 2 | H9: =СЗИ!P52 -> 1.07 | I9: =СЗИ!K52 -> 2 | J9: =СЗИ!I52 -> 0 | K9: =СЗИ!L52 -> 0 | L9: =IF(J9=I9," ",K9-J9) -> 0 | M9: =IF(H9<100, IF(K9>=G9,0,I9-K9), IF(H9<300, IF(K9>=F9,0,I9-K9), IF(K9>=E9,0,I9-K9))) -> 2 | N9: =СЗИ!Q52 -> - Разработать или Получить в Блоке ИБ ПАО Ростелеком типовое описание процесса обновления средств АВЗ _x000D_- Утвердить в Обществе ВНД, описывающий процесс обновления средств АВЗ
A10: СЗИ | B10: Защита от ВПО | C10: =СЗИ!B53 -> Процесс реагирования на события САВЗ | D10: =СЗИ!C53 -> СЗИ.ВПО.8 | E10: =СЗИ!D53 -> 4 | F10: =СЗИ!E53 -> 3 | G10: =СЗИ!F53 -> 2 | H10: =СЗИ!P53 -> 1.08 | I10: =СЗИ!K53 -> 2 | J10: =СЗИ!I53 -> 0 | K10: =СЗИ!L53 -> 0 | L10: =IF(J10=I10," ",K10-J10) -> 0 | M10: =IF(H10<100, IF(K10>=G10,0,I10-K10), IF(H10<300, IF(K10>=F10,0,I10-K10), IF(K10>=E10,0,I10-K10))) -> 2 | N10: =СЗИ!Q53 -> - Разработать или Получить в Блоке ИБ ПАО Ростелеком типовое описание процесса реагирования на события средств АВЗ _x000D_- Утвердить в Обществе ВНД, описывающий процесс реагирования на события средств АВЗ
A11: СЗИ | B11: Двухфакторная аутентификация пользователей (2FA) | C11: =СЗИ!B55 -> Использование OTP | D11: =СЗИ!C55 -> СЗИ.2FA.1 | E11: =СЗИ!D55 -> 5 | F11: =СЗИ!E55 -> 5 | G11: =СЗИ!F55 -> 3.2 | H11: =СЗИ!P55 -> 2.01 | I11: =СЗИ!K55 -> 3.2 | J11: =СЗИ!I55 -> 0 | K11: =СЗИ!L55 -> 0 | L11: =IF(J11=I11," ",K11-J11) -> 0 | M11: =IF(H11<100, IF(K11>=G11,0,I11-K11), IF(H11<300, IF(K11>=F11,0,I11-K11), IF(K11>=E11,0,I11-K11))) -> 3.2 | N11: =СЗИ!Q55 -> - Выбрать и протестировать OTP решения; - Выполнить проектирование; - Провести закупку и внедрение.
A12: СЗИ | B12: Двухфакторная аутентификация пользователей (2FA) | C12: =СЗИ!B56 -> Двухфакторная аутентификация используется для удаленного доступа работников к ресурсам Общества | D12: =СЗИ!C56 -> СЗИ.2FA.2 | E12: =СЗИ!D56 -> 5 | F12: =СЗИ!E56 -> 5 | G12: =СЗИ!F56 -> 5 | H12: =СЗИ!P56 -> 2.02 | I12: =СЗИ!K56 -> 5 | J12: =СЗИ!I56 -> 0 | K12: =СЗИ!L56 -> 0 | L12: =IF(J12=I12," ",K12-J12) -> 0 | M12: =IF(H12<100, IF(K12>=G12,0,I12-K12), IF(H12<300, IF(K12>=F12,0,I12-K12), IF(K12>=E12,0,I12-K12))) -> 5 | N12: =СЗИ!Q56 -> - Внедрить OTP для системы удаленного доступа
A13: СЗИ | B13: Двухфакторная аутентификация пользователей (2FA) | C13: =СЗИ!B57 -> Двухфакторная аутентификация используется для удаленного доступа подрядчиков к ресурсам Общества | D13: =СЗИ!C57 -> СЗИ.2FA.3 | E13: =СЗИ!D57 -> 5 | F13: =СЗИ!E57 -> 5 | G13: =СЗИ!F57 -> 3.2 | H13: =СЗИ!P57 -> 2.03 | I13: =СЗИ!K57 -> 3.2 | J13: =СЗИ!I57 -> 0 | K13: =СЗИ!L57 -> 0 | L13: =IF(J13=I13," ",K13-J13) -> 0 | M13: =IF(H13<100, IF(K13>=G13,0,I13-K13), IF(H13<300, IF(K13>=F13,0,I13-K13), IF(K13>=E13,0,I13-K13))) -> 3.2 | N13: =СЗИ!Q57 -> - Внедрить OTP для подрядчиков, выполняющих администрирование ИС Общества
A14: СЗИ | B14: Двухфакторная аутентификация пользователей (2FA) | C14: =СЗИ!B58 -> Двухфакторная аутентификация используется для привелигированных УЗ | D14: =СЗИ!C58 -> СЗИ.2FA.4 | E14: =СЗИ!D58 -> 5 | F14: =СЗИ!E58 -> 5 | G14: =СЗИ!F58 -> 3.2 | H14: =СЗИ!P58 -> 2.04 | I14: =СЗИ!K58 -> 3.2 | J14: =СЗИ!I58 -> 0 | K14: =СЗИ!L58 -> 0 | L14: =IF(J14=I14," ",K14-J14) -> 0 | M14: =IF(H14<100, IF(K14>=G14,0,I14-K14), IF(H14<300, IF(K14>=F14,0,I14-K14), IF(K14>=E14,0,I14-K14))) -> 3.2 | N14: =СЗИ!Q58 -> - Внедрить OTP для административного доступа к серверам ИС
A15: СЗИ | B15: Защита внешнего инфраструктурного периметра (CPT) | C15: =СЗИ!B60 -> Процент покрытия активов на внешнем периметре лицензиями/договорами | D15: =СЗИ!C60 -> СЗИ.CPT.1 | E15: =СЗИ!D60 -> 5 | F15: =СЗИ!E60 -> 5 | G15: =СЗИ!F60 -> 5 | H15: =СЗИ!P60 -> 3.01 | I15: =СЗИ!K60 -> 5 | J15: =СЗИ!I60 -> 0 | K15: =СЗИ!L60 -> 0 | L15: =IF(J15=I15," ",K15-J15) -> 0 | M15: =IF(H15<100, IF(K15>=G15,0,I15-K15), IF(H15<300, IF(K15>=F15,0,I15-K15), IF(K15>=E15,0,I15-K15))) -> 5 | N15: =СЗИ!Q60 -> - Приобрести средства CPT в достаточном объеме для контроля всех активов, опубликованных на периметре
A16: СЗИ | B16: Защита внешнего инфраструктурного периметра (CPT) | C16: =СЗИ!B61 -> Процент охваченных регулярным сканированием активов | D16: =СЗИ!C61 -> СЗИ.CPT.2 | E16: =СЗИ!D61 -> 4.75 | F16: =СЗИ!E61 -> 4.5 | G16: =СЗИ!F61 -> 3.75 | H16: =СЗИ!P61 -> 3.02 | I16: =СЗИ!K61 -> 3.75 | J16: =СЗИ!I61 -> 0 | K16: =СЗИ!L61 -> 0 | L16: =IF(J16=I16," ",K16-J16) -> 0 | M16: =IF(H16<100, IF(K16>=G16,0,I16-K16), IF(H16<300, IF(K16>=F16,0,I16-K16), IF(K16>=E16,0,I16-K16))) -> 3.75 | N16: =СЗИ!Q61 -> - Поставить периметр на контроль CPT, всего активов не менее: 75%
A17: СЗИ | B17: Защита внешнего инфраструктурного периметра (CPT) | C17: =СЗИ!B62 -> Внедрен процесс управления уязвимостями на периметре (CPT) | D17: =СЗИ!C62 -> СЗИ.CPT.3 | E17: =СЗИ!D62 -> 4 | F17: =СЗИ!E62 -> 3 | G17: =СЗИ!F62 -> 1 | H17: =СЗИ!P62 -> 3.03 | I17: =СЗИ!K62 -> 1 | J17: =СЗИ!I62 -> 0 | K17: =СЗИ!L62 -> 0 | L17: =IF(J17=I17," ",K17-J17) -> 0 | M17: =IF(H17<100, IF(K17>=G17,0,I17-K17), IF(H17<300, IF(K17>=F17,0,I17-K17), IF(K17>=E17,0,I17-K17))) -> 1 | N17: =СЗИ!Q62 -> - Разработать или Получить в Блоке ИБ ПАО Ростелеком типовое описание процесса контроля уязвимостей
A18: СЗИ | B18: Защита удаленного доступа (RA VPN) | C18: =СЗИ!B64 -> Наличие средств RA VPN | D18: =СЗИ!C64 -> СЗИ.RA-VPN.1 | E18: =СЗИ!D64 -> 5 | F18: =СЗИ!E64 -> 5 | G18: =СЗИ!F64 -> 5 | H18: =СЗИ!P64 -> 4.01 | I18: =СЗИ!K64 -> 5 | J18: =СЗИ!I64 -> 0 | K18: =СЗИ!L64 -> 0 | L18: =IF(J18=I18," ",K18-J18) -> 0 | M18: =IF(H18<100, IF(K18>=G18,0,I18-K18), IF(H18<300, IF(K18>=F18,0,I18-K18), IF(K18>=E18,0,I18-K18))) -> 5 | N18: =СЗИ!Q64 -> - Выбрать и протестировать решения RA VPN; - Выполнить проектирование; - Провести закупку и внедрение.
A19: СЗИ | B19: Защита удаленного доступа (RA VPN) | C19: =СЗИ!B65 -> Покрытие инфраструктуры средствами защищенного удаленного доступа | D19: =СЗИ!C65 -> СЗИ.RA-VPN.2 | E19: =СЗИ!D65 -> 5 | F19: =СЗИ!E65 -> 3.2 | G19: =СЗИ!F65 -> 3.2 | H19: =СЗИ!P65 -> 4.02 | I19: =СЗИ!K65 -> 3.2 | J19: =СЗИ!I65 -> 0 | K19: =СЗИ!L65 -> 0 | L19: =IF(J19=I19," ",K19-J19) -> 0 | M19: =IF(H19<100, IF(K19>=G19,0,I19-K19), IF(H19<300, IF(K19>=F19,0,I19-K19), IF(K19>=E19,0,I19-K19))) -> 3.2 | N19: =СЗИ!Q65 -> - Обеспечить возможность удаленного подключения к инфраструктуре Общества только с использованием RA VPN; - VPN должны требовать двухфакторной аутентификации.
A20: СЗИ | B20: Защита удаленного доступа (RA VPN) | C20: =СЗИ!B66 -> Осуществляется централизованное управление удаленным доступом | D20: =СЗИ!C66 -> СЗИ.RA-VPN.3 | E20: =СЗИ!D66 -> 5 | F20: =СЗИ!E66 -> 5 | G20: =СЗИ!F66 -> 3.2 | H20: =СЗИ!P66 -> 4.03 | I20: =СЗИ!K66 -> 3.2 | J20: =СЗИ!I66 -> 0 | K20: =СЗИ!L66 -> 0 | L20: =IF(J20=I20," ",K20-J20) -> 0 | M20: =IF(H20<100, IF(K20>=G20,0,I20-K20), IF(H20<300, IF(K20>=F20,0,I20-K20), IF(K20>=E20,0,I20-K20))) -> 3.2 | N20: =СЗИ!Q66 -> - Создать систему централизованного управления средствами VPN и обеспечить подключение к ней всех средств VPN
A21: СЗИ | B21: Защита удаленного доступа (RA VPN) | C21: =СЗИ!B67 -> Наличие действующего сертификата ФСБ России на этапе проведения аудита | D21: =СЗИ!C67 -> СЗИ.RA-VPN.4 | E21: =СЗИ!D67 -> 5 | F21: =СЗИ!E67 -> 5 | G21: =СЗИ!F67 -> 5 | H21: =СЗИ!P67 -> 4.04 | I21: =СЗИ!K67 -> 5 | J21: =СЗИ!I67 -> 0 | K21: =СЗИ!L67 -> 0 | L21: =IF(J21=I21," ",K21-J21) -> 0 | M21: =IF(H21<100, IF(K21>=G21,0,I21-K21), IF(H21<300, IF(K21>=F21,0,I21-K21), IF(K21>=E21,0,I21-K21))) -> 5 | N21: =СЗИ!Q67 -> - Если требования законодательства применимы, необходимо использовать только сертифицированные VPN
A22: СЗИ | B22: СКЗИ ГОСТ | C22: =СЗИ!B69 -> Защищены взаимодействия между площадками и ЦОД | D22: =СЗИ!C69 -> СЗИ.СКЗИ.1 | E22: =СЗИ!D69 -> 5 | F22: =СЗИ!E69 -> 5 | G22: =СЗИ!F69 -> 5 | H22: =СЗИ!P69 -> 5.01 | I22: =СЗИ!K69 -> 5 | J22: =СЗИ!I69 -> 0 | K22: =СЗИ!L69 -> 5 | L22: =IF(J22=I22," ",K22-J22) -> 5 | M22: =IF(H22<100, IF(K22>=G22,0,I22-K22), IF(H22<300, IF(K22>=F22,0,I22-K22), IF(K22>=E22,0,I22-K22))) -> 0 | N22: =СЗИ!Q69
A23: СЗИ | B23: СКЗИ ГОСТ | C23: =СЗИ!B70 -> Осуществляется централизованное управление СКЗИ | D23: =СЗИ!C70 -> СЗИ.СКЗИ.2 | E23: =СЗИ!D70 -> 5 | F23: =СЗИ!E70 -> 5 | G23: =СЗИ!F70 -> 3.2 | H23: =СЗИ!P70 -> 5.02 | I23: =СЗИ!K70 -> 3.2 | J23: =СЗИ!I70 -> 0 | K23: =СЗИ!L70 -> 3.2 | L23: =IF(J23=I23," ",K23-J23) -> 3.2 | M23: =IF(H23<100, IF(K23>=G23,0,I23-K23), IF(H23<300, IF(K23>=F23,0,I23-K23), IF(K23>=E23,0,I23-K23))) -> 0 | N23: =СЗИ!Q70
A24: СЗИ | B24: СКЗИ ГОСТ | C24: =СЗИ!B72 -> Наличие действующего сертификата ФСБ на этапе проведения аудита | D24: =СЗИ!C72 -> СЗИ.СКЗИ.4 | E24: =СЗИ!D72 -> 5 | F24: =СЗИ!E72 -> 5 | G24: =СЗИ!F72 -> 5 | H24: =СЗИ!P72 -> 5.04 | I24: =СЗИ!K72 -> 5 | J24: =СЗИ!I72 -> 0 | K24: =СЗИ!L72 -> 0 | L24: =IF(J24=I24," ",K24-J24) -> 0 | M24: =IF(H24<100, IF(K24>=G24,0,I24-K24), IF(H24<300, IF(K24>=F24,0,I24-K24), IF(K24>=E24,0,I24-K24))) -> 5 | N24: =СЗИ!Q72 -> - Если требования законодательства применимы, необходимо использовать только сертифицированные СКЗИ
A25: Мониторинг | B25: SIEM | C25: =Мониторинг!B45 -> Процент покрытия инфраструктуры лицензиями на мониторинг | D25: =Мониторинг!C45 -> МНТ.SIEM.1 | E25: =Мониторинг!D45 -> 5 | F25: =Мониторинг!E45 -> 5 | G25: =Мониторинг!F45 -> 0 | H25: =Мониторинг!P45 -> 6.01 | I25: =Мониторинг!K45 -> 0 | J25: =Мониторинг!I45 -> 0 | K25: =Мониторинг!L45 -> 0 | L25: =IF(J25=I25," ",K25-J25) | M25: =IF(H25<100, IF(K25>=G25,0,I25-K25), IF(H25<300, IF(K25>=F25,0,I25-K25), IF(K25>=E25,0,I25-K25))) -> 0 | N25: =Мониторинг!Q45
A26: Мониторинг | B26: SIEM | C26: =Мониторинг!B46 -> Процент покрытия инфраструктуры мониторингом | D26: =Мониторинг!C46 -> МНТ.SIEM.2 | E26: =Мониторинг!D46 -> 4.75 | F26: =Мониторинг!E46 -> 4.5 | G26: =Мониторинг!F46 -> 0 | H26: =Мониторинг!P46 -> 6.02 | I26: =Мониторинг!K46 -> 0 | J26: =Мониторинг!I46 -> 0 | K26: =Мониторинг!L46 -> 0 | L26: =IF(J26=I26," ",K26-J26) | M26: =IF(H26<100, IF(K26>=G26,0,I26-K26), IF(H26<300, IF(K26>=F26,0,I26-K26), IF(K26>=E26,0,I26-K26))) -> 0 | N26: =Мониторинг!Q46
A27: Мониторинг | B27: SIEM | C27: =Мониторинг!B47 -> Определен набор решающих правил и пороги страбатывания | D27: =Мониторинг!C47 -> МНТ.SIEM.3 | E27: =Мониторинг!D47 -> 5 | F27: =Мониторинг!E47 -> 3.2 | G27: =Мониторинг!F47 -> 0 | H27: =Мониторинг!P47 -> 6.03 | I27: =Мониторинг!K47 -> 0 | J27: =Мониторинг!I47 -> 0 | K27: =Мониторинг!L47 -> 0 | L27: =IF(J27=I27," ",K27-J27) | M27: =IF(H27<100, IF(K27>=G27,0,I27-K27), IF(H27<300, IF(K27>=F27,0,I27-K27), IF(K27>=E27,0,I27-K27))) -> 0 | N27: =Мониторинг!Q47
A28: Мониторинг | B28: SIEM | C28: =Мониторинг!B48 -> Осуществляется сбор событий, необходимых для детекта и обогащения в объеме, достаточном для решения задач (- создания, изменения, удаления субъектов и объектов доступа; - аутентификации (вход и выход субъектов); - авторизации (доступа субъектов к объектам); - запуска и остановки, удаления и остановки служб (ПО); - изменения настроек ПО и средств защиты информации; - обработки сетевого трафика (netflow)) | D28: =Мониторинг!C48 -> МНТ.SIEM.4 | E28: =Мониторинг!D48 -> 5 | F28: =Мониторинг!E48 -> 3.2 | G28: =Мониторинг!F48 -> 0 | H28: =Мониторинг!P48 -> 6.04 | I28: =Мониторинг!K48 -> 0 | J28: =Мониторинг!I48 -> 0 | K28: =Мониторинг!L48 -> 0 | L28: =IF(J28=I28," ",K28-J28) | M28: =IF(H28<100, IF(K28>=G28,0,I28-K28), IF(H28<300, IF(K28>=F28,0,I28-K28), IF(K28>=E28,0,I28-K28))) -> 0 | N28: =Мониторинг!Q48
A29: Мониторинг | B29: SIEM | C29: =Мониторинг!B49 -> Настроенные решающие правила соответствуют ТТР Блока ИБ | D29: =Мониторинг!C49 -> МНТ.SIEM.5 | E29: =Мониторинг!D49 -> 5 | F29: =Мониторинг!E49 -> 3.2 | G29: =Мониторинг!F49 -> 0 | H29: =Мониторинг!P49 -> 6.05 | I29: =Мониторинг!K49 -> 0 | J29: =Мониторинг!I49 -> 0 | K29: =Мониторинг!L49 -> 0 | L29: =IF(J29=I29," ",K29-J29) | M29: =IF(H29<100, IF(K29>=G29,0,I29-K29), IF(H29<300, IF(K29>=F29,0,I29-K29), IF(K29>=E29,0,I29-K29))) -> 0 | N29: =Мониторинг!Q49
A30: Мониторинг | B30: SIEM | C30: =Мониторинг!B50 -> Контролируются сетевые события | D30: =Мониторинг!C50 -> МНТ.SIEM.6 | E30: =Мониторинг!D50 -> 5 | F30: =Мониторинг!E50 -> 3.2 | G30: =Мониторинг!F50 -> 0 | H30: =Мониторинг!P50 -> 6.06 | I30: =Мониторинг!K50 -> 0 | J30: =Мониторинг!I50 -> 0 | K30: =Мониторинг!L50 -> 0 | L30: =IF(J30=I30," ",K30-J30) | M30: =IF(H30<100, IF(K30>=G30,0,I30-K30), IF(H30<300, IF(K30>=F30,0,I30-K30), IF(K30>=E30,0,I30-K30))) -> 0 | N30: =Мониторинг!Q50
A31: Мониторинг | B31: SIEM | C31: =Мониторинг!B51 -> Контролируются события ОС | D31: =Мониторинг!C51 -> МНТ.SIEM.7 | E31: =Мониторинг!D51 -> 5 | F31: =Мониторинг!E51 -> 3.2 | G31: =Мониторинг!F51 -> 0 | H31: =Мониторинг!P51 -> 6.07 | I31: =Мониторинг!K51 -> 0 | J31: =Мониторинг!I51 -> 0 | K31: =Мониторинг!L51 -> 0 | L31: =IF(J31=I31," ",K31-J31) | M31: =IF(H31<100, IF(K31>=G31,0,I31-K31), IF(H31<300, IF(K31>=F31,0,I31-K31), IF(K31>=E31,0,I31-K31))) -> 0 | N31: =Мониторинг!Q51
A32: Мониторинг | B32: SIEM | C32: =Мониторинг!B52 -> Контролируются события СУБД | D32: =Мониторинг!C52 -> МНТ.SIEM.8 | E32: =Мониторинг!D52 -> 5 | F32: =Мониторинг!E52 -> 3.2 | G32: =Мониторинг!F52 -> 0 | H32: =Мониторинг!P52 -> 6.08 | I32: =Мониторинг!K52 -> 0 | J32: =Мониторинг!I52 -> 0 | K32: =Мониторинг!L52 -> 0 | L32: =IF(J32=I32," ",K32-J32) | M32: =IF(H32<100, IF(K32>=G32,0,I32-K32), IF(H32<300, IF(K32>=F32,0,I32-K32), IF(K32>=E32,0,I32-K32))) -> 0 | N32: =Мониторинг!Q52
A33: Мониторинг | B33: SIEM | C33: =Мониторинг!B53 -> Контролируются события прикладных ИС | D33: =Мониторинг!C53 -> МНТ.SIEM.9 | E33: =Мониторинг!D53 -> 5 | F33: =Мониторинг!E53 -> 3.2 | G33: =Мониторинг!F53 -> 0 | H33: =Мониторинг!P53 -> 6.09 | I33: =Мониторинг!K53 -> 0 | J33: =Мониторинг!I53 -> 0 | K33: =Мониторинг!L53 -> 0 | L33: =IF(J33=I33," ",K33-J33) | M33: =IF(H33<100, IF(K33>=G33,0,I33-K33), IF(H33<300, IF(K33>=F33,0,I33-K33), IF(K33>=E33,0,I33-K33))) -> 0 | N33: =Мониторинг!Q53
A34: Мониторинг | B34: SIEM | C34: =Мониторинг!B54 -> Контроль событий СЗИ | D34: =Мониторинг!C54 -> МНТ.SIEM.10 | E34: =Мониторинг!D54 -> 5 | F34: =Мониторинг!E54 -> 3.2 | G34: =Мониторинг!F54 -> 0 | H34: =Мониторинг!P54 -> 6.1 | I34: =Мониторинг!K54 -> 0 | J34: =Мониторинг!I54 -> 0 | K34: =Мониторинг!L54 -> 0 | L34: =IF(J34=I34," ",K34-J34) | M34: =IF(H34<100, IF(K34>=G34,0,I34-K34), IF(H34<300, IF(K34>=F34,0,I34-K34), IF(K34>=E34,0,I34-K34))) -> 0 | N34: =Мониторинг!Q54
A35: Мониторинг | B35: SIEM | C35: =Мониторинг!B55 -> Контроль событий о действиях привелигированных пользователей | D35: =Мониторинг!C55 -> МНТ.SIEM.11 | E35: =Мониторинг!D55 -> 5 | F35: =Мониторинг!E55 -> 3.2 | G35: =Мониторинг!F55 -> 1.6 | H35: =Мониторинг!P55 -> 6.11 | I35: =Мониторинг!K55 -> 1.6 | J35: =Мониторинг!I55 -> 0 | K35: =Мониторинг!L55 -> 0 | L35: =IF(J35=I35," ",K35-J35) -> 0 | M35: =IF(H35<100, IF(K35>=G35,0,I35-K35), IF(H35<300, IF(K35>=F35,0,I35-K35), IF(K35>=E35,0,I35-K35))) -> 1.6 | N35: =Мониторинг!Q55 -> - Составить перчень привилегированных пользователей и групп; - Разработать решающие правила SIEM для выявления действий привилегированных пользователей; - Контролировать действия привилегированных пользователей в критичных ИС
A36: Мониторинг | B36: SIEM | C36: =Мониторинг!B56 -> Внедрен процесс управления сбоями и мониторинга работоспособности SIEM | D36: =Мониторинг!C56 -> МНТ.SIEM.12 | E36: =Мониторинг!D56 -> 4 | F36: =Мониторинг!E56 -> 3 | G36: =Мониторинг!F56 -> 0 | H36: =Мониторинг!P56 -> 6.12 | I36: =Мониторинг!K56 -> 0 | J36: =Мониторинг!I56 -> 0 | K36: =Мониторинг!L56 -> 0 | L36: =IF(J36=I36," ",K36-J36) | M36: =IF(H36<100, IF(K36>=G36,0,I36-K36), IF(H36<300, IF(K36>=F36,0,I36-K36), IF(K36>=E36,0,I36-K36))) -> 0 | N36: =Мониторинг!Q56
A37: Реагирование | B37: Планирование реагирования | C37: =Реагирование!B39 -> Процесс реагирования на инциденты ИБ | D37: =Реагирование!C39 -> РЕАГ.ПЛР.1 | E37: =Реагирование!D39 -> 4 | F37: =Реагирование!E39 -> 3 | G37: =Реагирование!F39 -> 1 | H37: =Реагирование!P39 -> 7.01 | I37: =Реагирование!K39 -> 1 | J37: =Реагирование!I39 -> 0 | K37: =Реагирование!L39 -> 0 | L37: =IF(J37=I37," ",K37-J37) -> 0 | M37: =IF(H37<100, IF(K37>=G37,0,I37-K37), IF(H37<300, IF(K37>=F37,0,I37-K37), IF(K37>=E37,0,I37-K37))) -> 1 | N37: =Реагирование!Q39 -> - Назначить ответственных за решение инцидентов ИБ, включая ответственного за коммуникации внутри и со сторонними компаниями; - Составить и актуализировать список заинтересованных лиц, которые должны получить уведомление об инциденте; - Для критичных инцидентов определить SLA и порядок действий по реагированию; - Автоматизировать процесс реагирования на инциденты ИБ с применением не специализированных средств.
A38: Реагирование | B38: Планирование реагирования | C38: =Реагирование!B40 -> Процесс категорирования инцидентов ИБ | D38: =Реагирование!C40 -> РЕАГ.ПЛР.2 | E38: =Реагирование!D40 -> 4 | F38: =Реагирование!E40 -> 3 | G38: =Реагирование!F40 -> 1 | H38: =Реагирование!P40 -> 7.02 | I38: =Реагирование!K40 -> 1 | J38: =Реагирование!I40 -> 0 | K38: =Реагирование!L40 -> 0 | L38: =IF(J38=I38," ",K38-J38) -> 0 | M38: =IF(H38<100, IF(K38>=G38,0,I38-K38), IF(H38<300, IF(K38>=F38,0,I38-K38), IF(K38>=E38,0,I38-K38))) -> 1 | N38: =Реагирование!Q40 -> - В Обществе неформально определить категории инцидентов ИБ
A39: Реагирование | B39: Планирование реагирования | C39: =Реагирование!B41 -> Определен мандат на действие в ходе реагирования на инцидент | D39: =Реагирование!C41 -> РЕАГ.ПЛР.3 | E39: =Реагирование!D41 -> 5 | F39: =Реагирование!E41 -> 3.2 | G39: =Реагирование!F41 -> 0 | H39: =Реагирование!P41 -> 7.03 | I39: =Реагирование!K41 -> 0 | J39: =Реагирование!I41 -> 0 | K39: =Реагирование!L41 -> 0 | L39: =IF(J39=I39," ",K39-J39) | M39: =IF(H39<100, IF(K39>=G39,0,I39-K39), IF(H39<300, IF(K39>=F39,0,I39-K39), IF(K39>=E39,0,I39-K39))) -> 0 | N39: =Реагирование!Q41
A40: Реагирование | B40: Планирование реагирования | C40: =Реагирование!B42 -> Планы реагирования совершенствуются по результатам тестирования и пост-анализа | D40: =Реагирование!C42 -> РЕАГ.ПЛР.4 | E40: =Реагирование!D42 -> 5 | F40: =Реагирование!E42 -> 3.2 | G40: =Реагирование!F42 -> 0 | H40: =Реагирование!P42 -> 7.04 | I40: =Реагирование!K42 -> 0 | J40: =Реагирование!I42 -> 0 | K40: =Реагирование!L42 -> 0 | L40: =IF(J40=I40," ",K40-J40) | M40: =IF(H40<100, IF(K40>=G40,0,I40-K40), IF(H40<300, IF(K40>=F40,0,I40-K40), IF(K40>=E40,0,I40-K40))) -> 0 | N40: =Реагирование!Q42
...

Sheet Управление ИБ
B1: Система управления ИБ | N1: =COUNTA(N2:N6960) -> 97
G40: =Расчет!$F$2 -> 45017 | H40: =Расчет!$H$2 -> 45444 | I40: 45657 | L40: =TODAY() -> 46038
B41: Категория | C41: Сокращенное наименование | D41: КБ3 | E41: КБ2 | F41: КБ1 | G41: Исторические данные | H41: Исторические данные | I41: Исторические данные | J41: 2026 | K41: Расчетный показатель 2025 | L41: Текущий показатель
B42: =B60 -> Система управления ИБ | C42: =C60 -> СУИБ | D42: =AVERAGE('Управление ИБ'!D61:D70) -> 5 | E42: =AVERAGE('Управление ИБ'!E61:E70) -> 4.64 | F42: =AVERAGE('Управление ИБ'!F61:F70) -> 2 | G42: =AVERAGE('Управление ИБ'!G61:G70) -> #DIV/0! | H42: =AVERAGE('Управление ИБ'!H61:H70) -> #DIV/0! | I42: =AVERAGE('Управление ИБ'!I61:I70) -> #DIV/0! | J42: =AVERAGE('Управление ИБ'!J61:J70) -> #DIV/0! | K42: =AVERAGE('Управление ИБ'!K61:K70) -> 2 | L42: =AVERAGE('Управление ИБ'!L61:L70) -> 3.32
B43: =B71 -> Управление рисками | C43: УР | D43: =AVERAGE('Управление ИБ'!D72:D76) -> 4.8 | E43: =AVERAGE('Управление ИБ'!E72:E76) -> 2 | F43: =AVERAGE('Управление ИБ'!F72:F76) -> 1 | G43: =AVERAGE('Управление ИБ'!G72:G76) -> #DIV/0! | H43: =AVERAGE('Управление ИБ'!H72:H76) -> #DIV/0! | I43: =AVERAGE('Управление ИБ'!I72:I76) -> #DIV/0! | J43: =AVERAGE('Управление ИБ'!J72:J76) -> #DIV/0! | K43: =AVERAGE('Управление ИБ'!K72:K76) -> 1 | L43: =AVERAGE('Управление ИБ'!L72:L76) -> 0
B44: =B107 -> Управление рисками в цепочке поставок | C44: ЦП | D44: =AVERAGE('Управление ИБ'!D108:D110) -> 5 | E44: =AVERAGE('Управление ИБ'!E108:E110) -> 3.2 | F44: =AVERAGE('Управление ИБ'!F108:F110) -> 1.6 | G44: =AVERAGE('Управление ИБ'!G108:G110) -> #DIV/0! | H44: =AVERAGE('Управление ИБ'!H108:H110) -> #DIV/0! | I44: =AVERAGE('Управление ИБ'!I108:I110) -> #DIV/0! | J44: =AVERAGE('Управление ИБ'!J108:J110) -> #DIV/0! | K44: =AVERAGE('Управление ИБ'!K108:K110) -> 1.6 | L44: =AVERAGE('Управление ИБ'!L108:L110) -> 0
B45: =B111 -> Инвентаризация | C45: ИН | D45: =AVERAGE('Управление ИБ'!D112:D124) -> 5 | E45: =AVERAGE('Управление ИБ'!E112:E124) -> 3.2 | F45: =AVERAGE('Управление ИБ'!F112:F124) -> 1.2307692 | G45: =AVERAGE('Управление ИБ'!G112:G124) -> #DIV/0! | H45: =AVERAGE('Управление ИБ'!H112:H124) -> #DIV/0! | I45: =AVERAGE('Управление ИБ'!I112:I124) -> #DIV/0! | J45: =AVERAGE('Управление ИБ'!J112:J124) -> #DIV/0! | K45: =AVERAGE('Управление ИБ'!K112:K124) -> 1.2307692 | L45: =AVERAGE('Управление ИБ'!L112:L124) -> 0.24615385
B46: =B101 -> Управление активами | C46: УА | D46: =AVERAGE('Управление ИБ'!D102:D106) -> 4.6 | E46: =AVERAGE('Управление ИБ'!E102:E106) -> 3.12 | F46: =AVERAGE('Управление ИБ'!F102:F106) -> 0.52 | G46: =AVERAGE('Управление ИБ'!G102:G106) -> #DIV/0! | H46: =AVERAGE('Управление ИБ'!H102:H106) -> #DIV/0! | I46: =AVERAGE('Управление ИБ'!I102:I106) -> #DIV/0! | J46: =AVERAGE('Управление ИБ'!J102:J106) -> #DIV/0! | K46: =AVERAGE('Управление ИБ'!K102:K106) -> 0.52 | L46: =AVERAGE('Управление ИБ'!L102:L106) -> 0.84
B47: =B168 -> Управление доступом | C47: =C168 -> УД | D47: =AVERAGE(D169:D178) -> 4.46 | E47: =AVERAGE(E169:E178) -> 3.26 | F47: =AVERAGE(F169:F178) -> 2.14 | G47: =AVERAGE(G169:G178) -> #DIV/0! | H47: =AVERAGE(H169:H178) -> #DIV/0! | I47: =AVERAGE(I169:I178) -> #DIV/0! | J47: =AVERAGE(J169:J178) -> #DIV/0! | K47: =AVERAGE(K169:K178) -> 2.14 | L47: =AVERAGE(L169:L178) -> 1.32
B48: =B179 -> Идентификация и аутентификация | C48: =C179 -> ИА | D48: =AVERAGE(D180:D188) -> 5 | E48: =AVERAGE(E180:E188) -> 4.6 | F48: =AVERAGE(F180:F188) -> 3.3111111 | G48: =AVERAGE(G180:G188) -> #DIV/0! | H48: =AVERAGE(H180:H188) -> #DIV/0! | I48: =AVERAGE(I180:I188) -> #DIV/0! | J48: =AVERAGE(J180:J188) -> #DIV/0! | K48: =AVERAGE(K180:K188) -> 3.3111111 | L48: =AVERAGE(L180:L188) -> 0
B49: =B189 -> Защита данных и информации | C49: =C189 -> Д | D49: =AVERAGE(D190:D193) -> 4.55 | E49: =AVERAGE(E190:E193) -> 3.7 | F49: =AVERAGE(F190:F193) -> 0.8 | G49: =AVERAGE(G190:G193) -> #DIV/0! | H49: =AVERAGE(H190:H193) -> #DIV/0! | I49: =AVERAGE(I190:I193) -> #DIV/0! | J49: =AVERAGE(J190:J193) -> #DIV/0! | K49: =AVERAGE(K190:K193) -> 0.8 | L49: =AVERAGE(L190:L193) -> 2.5
B50: =B125 -> Обеспечение доступности | C50: =C125 -> ОД | D50: =AVERAGE('Управление ИБ'!D126:D130) -> 5 | E50: =AVERAGE('Управление ИБ'!E126:E130) -> 3.92 | F50: =AVERAGE('Управление ИБ'!F126:F130) -> 0 | G50: =AVERAGE('Управление ИБ'!G129:G130) -> #DIV/0! | H50: =AVERAGE('Управление ИБ'!H129:H130) -> #DIV/0! | I50: =AVERAGE('Управление ИБ'!I126:I130) -> #DIV/0! | J50: =AVERAGE('Управление ИБ'!J126:J130) -> #DIV/0! | K50: =AVERAGE('Управление ИБ'!K126:K130) -> 0 | L50: =AVERAGE('Управление ИБ'!L126:L130) -> 0
B51: =B146 -> Персонал | C51: =C146 -> Люди | D51: =AVERAGE(D147:D149) -> 5 | E51: =AVERAGE(E147:E149) -> 5 | F51: =AVERAGE(F147:F149) -> 5 | G51: =AVERAGE(G147:G149) -> #DIV/0! | H51: =AVERAGE(H147:H149) -> #DIV/0! | I51: =AVERAGE(I147:I149) -> #DIV/0! | J51: =AVERAGE(J147:J149) -> #DIV/0! | K51: =AVERAGE(K147:K149) -> 5 | L51: =AVERAGE(L147:L149) -> 0
B52: =B156 -> Осведомленность пользователей и обучение персонала | C52: =C156 -> AW | D52: =AVERAGE(D157:D167) -> 5 | E52: =AVERAGE(E157:E167) -> 3.2 | F52: =AVERAGE(F157:F167) -> 1.6 | G52: =AVERAGE(G157:G167) -> #DIV/0! | H52: =AVERAGE(H157:H167) -> #DIV/0! | I52: =AVERAGE(I157:I167) -> #DIV/0! | J52: =AVERAGE(J157:J167) -> #DIV/0! | K52: =AVERAGE(K157:K167) -> 1.6 | L52: =AVERAGE(L157:L167) -> 0.14545455
B53: =B77 -> Процессы | C53: ПР | D53: =AVERAGE(D78:D100) -> 4.0869565 | E53: =AVERAGE(E78:E100) -> 2.8 | F53: =AVERAGE(F78:F100) -> 0.67826087 | G53: =AVERAGE(G78:G100) -> 0 | H53: =AVERAGE(H78:H100) -> 0 | I53: =AVERAGE(I78:I100) -> 0 | J53: =AVERAGE(J78:J100) -> 0 | K53: =AVERAGE(K78:K100) -> 0.67826087 | L53: =AVERAGE(L78:L100) -> 0.24347826
B54: =B131 -> Безопасная разработка | C54: =C131 -> БР | D54: =AVERAGE(D132:D145)*IF(БР="да",1,0) -> 4.9285714 | E54: =AVERAGE(E132:E145)*IF(БР="да",1,0) -> 3.8285714 | F54: =AVERAGE(F132:F145)*IF(БР="да",1,0) -> 0.98571429 | G54: =AVERAGE(G132:G145) -> #DIV/0! | H54: =AVERAGE(H132:H145) -> #DIV/0! | I54: =AVERAGE(I132:I145) -> #DIV/0! | J54: =AVERAGE(J132:J145) -> #DIV/0! | K54: =AVERAGE(K132:K145) -> 0.98571429 | L54: =AVERAGE(L132:L145) -> 0
B55: =B150 -> Физический доступ | C55: =C150 -> ФД | D55: =AVERAGE(D151:D155) -> 5 | E55: =AVERAGE(E151:E155) -> 4.64 | F55: =AVERAGE(F151:F155) -> 4.32 | G55: =AVERAGE(G151:G155) -> #DIV/0! | H55: =AVERAGE(H151:H155) -> #DIV/0! | I55: =AVERAGE(I151:I155) -> #DIV/0! | J55: =AVERAGE(J151:J155) -> #DIV/0! | K55: =AVERAGE(K151:K155) -> 4.32 | L55: =AVERAGE(L151:L155) -> 0
P59: Приоритет | Q59: Очередь 1 (КБ1) | S59: Очередь 2 (КБ2) | U59: Очередь 3 (КБ3)
B60: Система управления ИБ | C60: СУИБ | P60: =VLOOKUP(B60,Приоритет!$G$9:$K$52,5,0) -> 14 | Q60: СУИБ | R60: =P60+200 -> 214 | S60: СУИБ | T60: =P60+300 -> 314 | U60: СУИБ
B61: Утверждена Политика информационной безопасности Общества | C61: СУИБ.УР.1 | D61: 5 | E61: 5 | F61: 5 | K61: 5 | L61: =VALUE(LEFT(N61,3)) -> 5 | M61: =L61-K61 -> 0 | N61: 5 -да | P61: =P60+0.01 -> 14.01 | Q61: =IF(($L61-$F61)>=0,"", "- Разработать или Получить в Блоке ИБ ПАО Ростелеком типовую политику ИБ; - Утвердить в Обществе Политику ИБ") | R61: =R60+0.01 -> 214.01 | S61: =IF(($L61-$E61)>=0,"","") | T61: =T60+0.01 -> 314.01 | U61: =IF(($L61-$D61)>=0,"","")
B62: Назначено лицо, ответственное за обеспечение информационной безопасности | C62: СУИБ.УР.10 | D62: 5 | E62: 5 | F62: 5 | K62: 5 | L62: =VALUE(LEFT(N62,3)) -> 5 | M62: =L62-K62 -> 0 | N62: 5 -да | P62: =P61+0.01 -> 14.02 | Q62: =IF(($L62-$F62)>=0,"","- Определить полномочия ответственного за обеспечение ИБ в Обществе."&" - Подготовить и утвердить приказ об ответственном за обеспечение ИБ в Обществе") | R62: =R61+0.01 -> 214.02 | T62: =T61+0.01 -> 314.02
B63: Создано подразделение по ИБ или задачи возложены на подразделение | C63: СУИБ.УР.11 | D63: 5 | E63: 5 | F63: 5 | K63: 5 | L63: =VALUE(LEFT(N63,3)) -> 5 | M63: =L63-K63 -> 0 | N63: 5 -да | P63: =P62+0.01 -> 14.03 | Q63: =IF(($L63-$F63)>=0,"", " - Определить полномочия для подразделения, ответственное за ИБ (как минимум уровня отдела ИБ). - Подготовить положение о подразделении, обеспечивающим ИБ в Обществе."&" - Создать выделенное подразделение, ответственное за ИБ (как минимум уровня отдела ИБ): - Утвердить приказом по орг. структуре создание подразделения ИБ."&" - Утвердить положение о подразделении, обеспечивающим ИБ в Обществе. - Распоряжением/приказом определили подразделение ИБ, как подразделение Общества, ответственное за обеспечение ИБ") | R63: =R62+0.01 -> 214.03 | T63: =T62+0.01 -> 314.03
B64: Определены цели обеспечения ИБ | C64: СУИБ.УР.2 | D64: 5 | E64: 5 | F64: 0 | K64: 0 | L64: =VALUE(LEFT(N64,3)) -> 5 | M64: =L64-K64 -> 5 | N64: 5 -да | P64: =P63+0.01 -> 14.04 | Q64: =IF(($L64-$F64)>=0,"",) | R64: =R63+0.01 -> 214.04 | S64: =IF(($L64-$E64)>=0,"", "- Провести анализ целей Общества в области ИБ и отразить в Политике ИБ, стратегии развития или планах развития") | T64: =T63+0.01 -> 314.04 | U64: =IF(($L64-$D64)>=0,""," ")
